Workbook

Sheet Metrics
A1: =Invoice!A8+OrderingShipping!A9 -> 233 | B1: Total Records
A2: =COUNTA(B11:B4994) -> 59 | B2: Total Attributes
A3: =A1*A2 -> 13747 | B3: Total to Cleanse
A4: =(COUNTIF(L:L,100%)*A1) -> 13281 | B4: Cleansed Attributes
A5: =A3-A4 -> 466 | B5: Dirty Attributes Remaining
A6: =AVERAGEIFS(L:L, G:G, "Yes", H:H, "Business", M:M, "<>Phase 1 - Non STIBO") -> 0.99984672 | B6: Av. % Complete
A7: =Invoice!B7/Invoice!A8 -> 1 | B7: Complete Invoice Records
A8: =OrderingShipping!B7/OrderingShipping!A8 -> 1 | B8: Complete O/S Records
A9: TBC | B9: Completed Non STIBO
A10: Tab | B10: Field Name | C10: Field Description | D10: Source location | E10: Source Field Name | F10: Field Type | G10: Mandatory? | H10: Responsible | I10: Incomplete | J10: Invalid | K10: Total | L10: % Complete | M10: MVP/Phase1 | N10: Okay to go in Jeeves/File? | O10: General Comment | P10: Transformation RULE | Q10: Transformation comment
A11: Invoice | B11: =Invoice!F6 -> Company Registration Number | C11: Add Company Registration Number | D11: STIBO | E11: Company Registration Number | F11: Alphanumeric | G11: Yes | H11: Business | I11: =Invoice!G7 -> 0 | J11: =Invoice!H7 -> 0 | K11: =Invoice!$A$8 -> 233 | L11: =IFERROR(((K11-J11)/K11),"0%") -> 1 | M11: MVP | N11: FALSE
A12: Invoice | B12: =Invoice!I6 -> VAT | C12: Vendor VAT Number | D12: STIBO | E12: VAT | F12: Text | G12: No | H12: Business | I12: =Invoice!J7 -> 0 | J12: =Invoice!K7 -> 0 | K12: =Invoice!$A$8 -> 233 | L12: =IFERROR(((K12-J12)/K12),"0%") -> 1 | M12: MVP | N12: FALSE
A13: Invoice | B13: =Invoice!L6 -> Address Line 1 | C13: Address field | D13: STIBO | E13: Address Line 1 | F13: Text | G13: Yes | H13: Business | I13: =Invoice!M7 -> 0 | J13: =Invoice!N7 -> 0 | K13: =Invoice!$A$8 -> 233 | L13: =IFERROR(((K13-J13)/K13),"0%") -> 1 | M13: MVP | N13: FALSE
A14: Invoice | B14: =Invoice!O6 -> Address Line 2 | C14: Address field | D14: STIBO | E14: Address Line 2 | F14: Text | G14: No | H14: Business | I14: =Invoice!P7 -> 0 | J14: =Invoice!Q7 -> 0 | K14: =Invoice!$A$8 -> 233 | L14: =IFERROR(((K14-J14)/K14),"0%") -> 1 | M14: MVP | N14: FALSE
A15: Invoice | B15: =Invoice!R6 -> Town/City | C15: Address field | D15: STIBO | E15: Town/City | F15: Text | G15: Yes | H15: Business | I15: =Invoice!S7 -> 0 | J15: =Invoice!T7 -> 0 | K15: =Invoice!$A$8 -> 233 | L15: =IFERROR(((K15-J15)/K15),"0%") -> 1 | M15: MVP | N15: FALSE
A16: Invoice | B16: =Invoice!U6 -> County/District | C16: Address field | D16: STIBO | E16: County/District | F16: Text | G16: No | H16: Business | I16: =Invoice!V7 -> 0 | J16: =Invoice!W7 -> 0 | K16: =Invoice!$A$8 -> 233 | L16: =IFERROR(((K16-J16)/K16),"0%") -> 1 | M16: MVP | N16: FALSE
A17: Invoice | B17: =Invoice!X6 -> Zip/Postal Code | C17: Address field | D17: STIBO | E17: Zip/Postal Code | F17: Text | G17: Yes | H17: Business | I17: =Invoice!Y7 -> 0 | J17: =Invoice!Z7 -> 0 | K17: =Invoice!$A$8 -> 233 | L17: =IFERROR(((K17-J17)/K17),"0%") -> 1 | M17: MVP | N17: FALSE
A18: Invoice | B18: =Invoice!AA6 -> Country | C18: ISO-2 country code | D18: STIBO | E18: Country | F18: LOV | G18: Yes | H18: Business | I18: =Invoice!AB7 -> 0 | J18: =Invoice!AC7 -> 0 | K18: =Invoice!$A$8 -> 233 | L18: =IFERROR(((K18-J18)/K18),"0%") -> 1 | M18: MVP | N18: FALSE
A19: Invoice | B19: =Invoice!AD6 -> Currency Code | C19: 3 characters code | D19: STIBO | E19: Currency Code | F19: LOV | G19: Yes | H19: Business | I19: =Invoice!AE7 -> 0 | J19: =Invoice!AF7 -> 0 | K19: =Invoice!$A$8 -> 233 | L19: =IFERROR(((K19-J19)/K19),"0%") -> 1 | M19: MVP | N19: FALSE
A20: Invoice | B20: =Invoice!AG6 -> Payment Terms | C20: Select Payment terms for Invoice vendor | D20: STIBO | E20: Payment Terms | F20: LOV | G20: Yes | H20: Business | I20: =Invoice!AH7 -> 0 | J20: =Invoice!AI7 -> 0 | K20: =Invoice!$A$8 -> 233 | L20: =IFERROR(((K20-J20)/K20),"0%") -> 1 | M20: MVP | N20: FALSE
A21: Invoice | B21: =Invoice!AJ6 -> Method of Payment | C21: Select method of payment for Invoice vendor | D21: Jeeves | E21: UtbSlag | F21: LOV | G21: Yes | H21: Business | I21: =Invoice!AK7 -> 0 | J21: =Invoice!AL7 -> 0 | K21: =Invoice!$A$8 -> 233 | L21: =IFERROR(((K21-J21)/K21),"0%") -> 1 | M21: Phase 1 | N21: FALSE
A22: Invoice | B22: =Invoice!AM6 -> VAT Group | C22: Vendor VAT grouping | D22: Jeeves | E22: LevKategori | F22: LOV | G22: Yes | H22: Business | I22: =Invoice!AN7 -> 0 | J22: =Invoice!AO7 -> 0 | K22: =Invoice!$A$8 -> 233 | L22: =IFERROR(((K22-J22)/K22),"0%") -> 1 | M22: Phase 1 | N22: FALSE
A23: Invoice | B23: =Invoice!AP6 -> Known As Name | C23: Name field | D23: NA | F23: Text | G23: No | H23: Business | I23: =Invoice!AQ7 -> 0 | J23: =Invoice!AR7 -> 0 | K23: =Invoice!$A$8 -> 233 | L23: =IFERROR(((K23-J23)/K23),"0%") -> 1 | M23: Phase 1 | N23: FALSE
A24: Invoice | B24: =Invoice!AS6 -> Legal Name | C24: Name field | D24: STIBO | F24: Text | G24: Yes | H24: Business | I24: =Invoice!AT7 -> 0 | J24: =Invoice!AU7 -> 0 | K24: =Invoice!$A$8 -> 233 | L24: =IFERROR(((K24-J24)/K24),"0%") -> 1 | M24: Phase 1 | N24: FALSE
A25: Invoice | B25: =Invoice!AV6 -> Search Name | C25: Name field | F25: Text | G25: Yes | H25: OSD | I25: =Invoice!AW7 -> 0 | J25: =Invoice!AX7 -> 0 | K25: =Invoice!$A$8 -> 233 | L25: =IFERROR(((K25-J25)/K25),"0%") -> 1 | M25: Phase 1 | N25: FALSE
A26: Invoice | B26: =Invoice!AY6 -> EU Master Vendor | C26: Europe level vendor grouping | D26: NA | F26: LOV | G26: Yes | H26: OSD | I26: =Invoice!AZ7 -> 0 | J26: =Invoice!BA7 -> 1 | K26: =Invoice!$A$8 -> 233 | L26: =IFERROR(((K26-J26)/K26),"0%") -> 0.99570815 | M26: Phase 1 | N26: FALSE
A27: Invoice | B27: =Invoice!BB6 -> Certificate of Insurance | C27: End date for insurance certificate | D27: NA | F27: Date | G27: No | H27: Business | I27: =Invoice!BC7 -> 0 | J27: =Invoice!BD7 -> 0 | K27: =Invoice!$A$8 -> 233 | L27: =IFERROR(((K27-J27)/K27),"0%") -> 1 | M27: Phase 1 | N27: FALSE
A28: Invoice | B28: =Invoice!BE6 -> Hold Harmless | C28: End date for Hold Harmless Agreement | D28: NA | F28: Date | G28: No | H28: Business | I28: =Invoice!BF7 -> 0 | J28: =Invoice!BG7 -> 0 | K28: =Invoice!$A$8 -> 233 | L28: =IFERROR(((K28-J28)/K28),"0%") -> 1 | M28: Phase 1 | N28: FALSE
A29: Invoice | B29: =Invoice!BH6 -> GLN | C29: Global Location Number | F29: Numeric | G29: No | H29: Business | I29: =Invoice!BI7 -> 0 | J29: =Invoice!BJ7 -> 0 | K29: =Invoice!$A$8 -> 233 | L29: =IFERROR(((K29-J29)/K29),"0%") -> 1 | M29: Phase 1 | N29: FALSE
A30: Invoice | B30: =Invoice!BK6 -> Address Purpose | C30: Select Address Purpose, defaulted to Invoice | D30: NA | F30: LOV | G30: Yes | H30: Business | I30: =Invoice!BL7 -> 1 | J30: =Invoice!BM7 -> 1 | K30: =Invoice!$A$8 -> 233 | L30: =IFERROR(((K30-J30)/K30),"0%") -> 0.99570815 | M30: Phase 1 | N30: FALSE
A31: Invoice | B31: =Invoice!BN6 -> Vendor Status | C31: Active/Delisted Status | D31: Extern file | F31: LOV | G31: Yes | H31: Business | I31: =Invoice!BO7 -> 0 | J31: =Invoice!BP7 -> 0 | K31: =Invoice!$A$8 -> 233 | L31: =IFERROR(((K31-J31)/K31),"0%") -> 1 | M31: Phase 1 | N31: FALSE | O31: WIP (done 6 oct)
A32: Invoice | B32: =Invoice!BQ6 -> Intercompany/Trading Partner | C32: Select if Vendor is Sysco company | F32: LOV | G32: No | H32: Business | I32: =Invoice!BR7 -> 0 | J32: =Invoice!BS7 -> 0 | K32: =Invoice!$A$8 -> 233 | L32: =IFERROR(((K32-J32)/K32),"0%") -> 1 | M32: Phase 1 | N32: FALSE
A33: Invoice | B33: =Invoice!BT6 -> Duty Paid/Bond | C33: Select if alcoholic items are duty paid/bond. Specific to Classic Drinks Ireland | D33: NA | F33: LOV | G33: No | H33: Business | I33: =Invoice!BU7 -> 0 | J33: =Invoice!BV7 -> 0 | K33: =Invoice!$A$8 -> 233 | L33: =IFERROR(((K33-J33)/K33),"0%") -> 1 | M33: Phase 1 | N33: FALSE
A34: OrderingShipping | B34: =OrderingShipping!F6 -> Address Line 1 | C34: Address field | D34: STIBO | E34: Address Line 1 | F34: Text | G34: Yes | H34: Business | I34: =OrderingShipping!G7 -> 0 | J34: =OrderingShipping!H7 -> 0 | K34: =OrderingShipping!$A$8 -> 101 | L34: =IFERROR(((K34-J34)/K34),"0%") -> 1 | M34: MVP | N34: FALSE
A35: OrderingShipping | B35: =OrderingShipping!I6 -> Address Line 2 | C35: Address field | D35: STIBO | E35: Address Line 2 | F35: Text | G35: No | H35: Business | I35: =OrderingShipping!J7 -> 0 | J35: =OrderingShipping!K7 -> 0 | K35: =OrderingShipping!$A$8 -> 101 | L35: =IFERROR(((K35-J35)/K35),"0%") -> 1 | M35: MVP | N35: FALSE
A36: OrderingShipping | B36: =OrderingShipping!L6 -> Town/City | C36: Address field | D36: STIBO | E36: Town/City | F36: Text | G36: Yes | H36: Business | I36: =OrderingShipping!M7 -> 0 | J36: =OrderingShipping!N7 -> 0 | K36: =OrderingShipping!$A$8 -> 101 | L36: =IFERROR(((K36-J36)/K36),"0%") -> 1 | M36: MVP | N36: FALSE
A37: OrderingShipping | B37: =OrderingShipping!O6 -> County/District | C37: Address field | D37: STIBO | E37: County/District | F37: Text | G37: No | H37: Business | I37: =OrderingShipping!P7 -> 0 | J37: =OrderingShipping!Q7 -> 0 | K37: =OrderingShipping!$A$8 -> 101 | L37: =IFERROR(((K37-J37)/K37),"0%") -> 1 | M37: MVP | N37: FALSE
A38: OrderingShipping | B38: =OrderingShipping!R6 -> Zip/Postal Code | C38: Address field | D38: STIBO | E38: Zip/Postal Code | F38: Text | G38: Yes | H38: Business | I38: =OrderingShipping!S7 -> 0 | J38: =OrderingShipping!T7 -> 0 | K38: =OrderingShipping!$A$8 -> 101 | L38: =IFERROR(((K38-J38)/K38),"0%") -> 1 | M38: MVP | N38: FALSE
A39: OrderingShipping | B39: =OrderingShipping!U6 -> Country | C39: ISO-2 country code | D39: STIBO | E39: Country | F39: LOV | G39: Yes | H39: Business | I39: =OrderingShipping!V7 -> 0 | J39: =OrderingShipping!W7 -> 0 | K39: =OrderingShipping!$A$8 -> 101 | L39: =IFERROR(((K39-J39)/K39),"0%") -> 1 | M39: MVP | N39: FALSE
A40: OrderingShipping | B40: =OrderingShipping!X6 -> Delivery Term | C40: Select Terms of delivery | D40: Jeeves | E40: IncoTerms | F40: LOV | G40: Yes | H40: Business | I40: =OrderingShipping!Y7 -> 0 | J40: =OrderingShipping!Z7 -> 0 | K40: =OrderingShipping!$A$8 -> 101 | L40: =IFERROR(((K40-J40)/K40),"0%") -> 1 | M40: Phase 1 | N40: FALSE
...

Sheet Invoice
A1: Mandatory | C1: N/A | D1: N/A | F1: Yes | I1: No | L1: Yes | O1: No | R1: Yes | U1: No | X1: Yes | AA1: Yes | AD1: Yes | AG1: Yes | AJ1: Yes | AM1: Yes | AP1: No | AS1: Yes | AV1: Yes | AY1: Yes | BB1: No | BE1: No | BH1: No | BK1: Yes | BN1: Yes | BQ1: Yes + BR | BT1: No | BW1: No
A2: Main checks | C2: N/A | D2: N/A | F2: Make sure the length is within limit and have no special characters. | I2: Make sure the length is within limit and have no special characters. | L2: Make sure the name length is within limit and have only allowed special characters. | O2: Make sure the name length is within limit and have only allowed special characters. | R2: Make sure the name length is within limit and have only allowed special characters. | U2: Make sure the name length is within limit and have only allowed special characters. | X2: Make sure the name length is within limit and have only allowed special characters. | AA2: Analyse current data to new harmonized table and cleanse to standard | AD2: Analyse current data to new harmonized table and cleanse to standard | AG2: Check if payment term is stored in the system, if not, setup a way to collect and align with the harmozined list of values. | AJ2: Check if payment method is stored in the system, if not, setup a way to collect and align with the harmozined list of values. | AM2: Analyze current data and compare to new harmonized table | AP2: Make sure the name length is within limit and have only allowed special characters. | AS2: Make sure the name length is within limit and have only allowed special characters. | AV2: Auto-populated, OSD team to manage | AY2: No cleanup required, OSD team to manage | BB2: Check if data is collected in local ERP. Make sure the certfication date is in correct Date format | BE2: Check if data is collected in local ERP. Make sure the certfication date is in correct Date format | BH2: No special characters/spaces are allowed, numeric field | BK2: Analyze current data if Address purpose is collected. | BN2: Analyze current data and populate if a local vendor should be Active/Delisted | BQ2: Analyse current data to new harmonized table and cleanse to standard | BT2: Analyse current data to new harmonized table and cleanse to standard
A3: Base type | C3: N/A | D3: N/A | F3: Alphanumeric | I3: Text | L3: Text | O3: Text | R3: Text | U3: Text | X3: Text | AA3: LOV | AD3: LOV | AG3: LOV | AJ3: LOV | AM3: LOV | AP3: Text | AS3: Text | AV3: Text | AY3: LOV | BB3: Date | BE3: Date | BH3: Numeric | BK3: LOV | BN3: LOV | BQ3: LOV | BT3: LOV
A4: Char length | C4: N/A | D4: N/A | F4: 30 | I4: 20 | L4: 8 | O4: 80 | R4: 60 | U4: 60 | X4: 80 | AA4: N/A | AD4: N/A | AG4: N/A | AJ4: N/A | AM4: N/A | AP4: 80 | AS4: 80 | AV4: 20 | AY4: N/A | BB4: N/A | BE4: N/A | BH4: 13 | BK4: N/A | BN4: N/A | BQ4: N/A | BT4: N/A
A5: Special char | C5: N/A | D5: N/A | F5: No | I5: No | L5: Allowed list with exceptions | O5: Allowed list with exceptions | R5: Allowed list only | U5: Allowed list only | X5: Allowed list only | AA5: N/A | AD5: N/A | AG5: N/A | AJ5: N/A | AM5: N/A | AP5: Check MDD for Special Characters | AS5: Check MDD for Special Characters | AV5: Check MDD for Special Characters | AY5: N/A | BB5: N/A | BE5: N/A | BH5: None | BK5: N/A | BN5: N/A | BQ5: N/A | BT5: N/A
A6: Header | C6: Invoice SUVC | D6: Vendor Name | E6: Vendor Account Group | F6: Company Registration Number | G6: Complete | H6: Valid | I6: VAT | J6: Complete | K6: Valid | L6: Address Line 1 | M6: Complete | N6: Valid | O6: Address Line 2 | P6: Complete | Q6: Valid | R6: Town/City | S6: Complete | T6: Valid | U6: County/District | V6: Complete | W6: Valid | X6: Zip/Postal Code | Y6: Complete | Z6: Valid | AA6: Country | AB6: Complete | AC6: Valid | AD6: Currency Code | AE6: Complete | AF6: Valid | AG6: Payment Terms | AH6: Complete | AI6: Valid | AJ6: Method of Payment | AK6: Complete | AL6: Valid | AM6: VAT Group | AN6: Complete | AO6: Valid | AP6: Known As Name | AQ6: Complete | AR6: Valid | AS6: Legal Name | AT6: Complete | AU6: Valid | AV6: Search Name | AW6: Complete | AX6: Valid | AY6: EU Master Vendor | AZ6: Complete | BA6: Valid | BB6: Certificate of Insurance | BC6: Complete | BD6: Valid | BE6: Hold Harmless | BF6: Complete | BG6: Valid | BH6: GLN | BI6: Complete | BJ6: Valid | BK6: Address Purpose | BL6: Complete | BM6: Valid | BN6: Vendor Status | BO6: Complete | BP6: Valid | BQ6: Intercompany/Trading Partner | BR6: Complete | BS6: Valid | BT6: Duty Paid/Bond | BU6: Complete | BV6: Valid | BW6: Is Intercompany | BX6: Complete | BY6: Valid | BZ6: Menigo Focus
A7: Example | B7: =+COUNTIF(B8:B1048570,0) -> 233 | C7: 207622 | D7: Ciaran's Cookware | E7: Trade | F7: A123456 | G7: =COUNTIF(G$8:G$1295,FALSE) -> 0 | H7: =COUNTIF(H$8:H$1295,FALSE) -> 0 | I7: A123456 | J7: =COUNTIF(J$8:J$1295,FALSE) -> 0 | K7: =COUNTIF(K$8:K$1295,FALSE) -> 0 | L7: Unit 1 | M7: =COUNTIF(M$8:M$1295,FALSE) -> 0 | N7: =COUNTIF(N$8:N$1295,FALSE) -> 0 | O7: 1 Pixie Way | P7: =COUNTIF(P$8:P$1295,FALSE) -> 0 | Q7: =COUNTIF(Q$8:Q$1295,FALSE) -> 0 | R7: Los Angeles | S7: =COUNTIF(S$8:S$1295,FALSE) -> 0 | T7: =COUNTIF(T$8:T$1295,FALSE) -> 0 | U7: California | V7: =COUNTIF(V$8:V$1295,FALSE) -> 0 | W7: =COUNTIF(W$8:W$1295,FALSE) -> 0 | X7: 123456 | Y7: =COUNTIF(Y$8:Y$1295,FALSE) -> 0 | Z7: =COUNTIF(Z$8:Z$1295,FALSE) -> 0 | AA7: US | AB7: =COUNTIF(AB$8:AB$1295,FALSE) -> 0 | AC7: =COUNTIF(AC$8:AC$1295,FALSE) -> 0 | AD7: GBP | AE7: =COUNTIF(AE$8:AE$1295,FALSE) -> 0 | AF7: =COUNTIF(AF$8:AF$1295,FALSE) -> 0 | AG7: V_10EOM | AH7: =COUNTIF(AH$8:AH$1295,FALSE) -> 0 | AI7: =COUNTIF(AI$8:AI$1295,FALSE) -> 0 | AJ7: V_DD_BASE | AK7: =COUNTIF(AK$8:AK$1295,FALSE) -> 0 | AL7: =COUNTIF(AL$8:AL$1295,FALSE) -> 0 | AM7: S-DOM | AN7: =COUNTIF(AN$8:AN$1295,FALSE) -> 0 | AO7: =COUNTIF(AO$8:AO$1295,FALSE) -> 0 | AP7: Kraft Heinz Brakes Company | AQ7: =COUNTIF(AQ$8:AQ$1295,FALSE) -> 0 | AR7: =COUNTIF(AR$8:AR$1295,FALSE) -> 0 | AS7: Kraft Heinz GB Co. Limited | AT7: =COUNTIF(AT$8:AT$1295,FALSE) -> 0 | AU7: =COUNTIF(AU$8:AU$1295,FALSE) -> 0 | AV7: Kraft Heinz Brakes C | AW7: =COUNTIF(AW$8:AW$1295,FALSE) -> 0 | AX7: =COUNTIF(AX$8:AX$1295,FALSE) -> 0 | AY7: Kraft | AZ7: =COUNTIF(AZ$8:AZ$1295,FALSE) -> 0 | BA7: =COUNTIF(BA$8:BA$1295,FALSE) -> 1 | BB7: 45742 | BC7: =COUNTIF(BC$8:BC$1295,FALSE) -> 0 | BD7: =COUNTIF(BD$8:BD$1295,FALSE) -> 0 | BE7: 45742 | BF7: =COUNTIF(BF$8:BF$1295,FALSE) -> 0 | BG7: =COUNTIF(BG$8:BG$1295,FALSE) -> 0 | BH7: GB02 | BI7: =COUNTIF(BI$8:BI$1295,FALSE) -> 0 | BJ7: =COUNTIF(BJ$8:BJ$1295,FALSE) -> 0 | BK7: Director of Sales Address | BL7: =COUNTIF(BL$8:BL$1295,FALSE) -> 1 | BM7: =COUNTIF(BM$8:BM$1295,FALSE) -> 1 | BN7: Active | BO7: =COUNTIF(BO$8:BO$1295,FALSE) -> 0 | BP7: =COUNTIF(BP$8:BP$1295,FALSE) -> 0 | BQ7: GB02 | BR7: =COUNTIF(BR$8:BR$1295,FALSE) -> 0 | BS7: =COUNTIF(BS$8:BS$1295,FALSE) -> 0 | BT7: Duty Paid | BU7: =COUNTIF(BU$8:BU$1295,FALSE) -> 0 | BV7: =COUNTIF(BV$8:BV$1295,FALSE) -> 0 | BW7: Yes | BX7: =COUNTIF(BX$8:BX$1295,FALSE) -> 0 | BY7: =COUNTIF(BY$8:BY$1295,FALSE) -> 0
A8: =COUNTA($C$8:$C$1295) -> 233 | B8: =COUNTIF(C8:XFD8,"FALSE") -> 0 | C8: 217939 | D8: SVENSKA INSJÖFISKARENAS AB | E8: Trade | F8: 5562077049 | G8: =IF(NOT(ISBLANK($C8)),IF(NOT(ISBLANK(F8)),TRUE,FALSE),"") -> TRUE | H8: {=IF(NOT(ISBLANK($C8)),AND(G8=TRUE,LEN(F8)<30,NOT(ISNUMBER(FIND('List of Values'!$C$2:$C$20,F8)))),"")} -> TRUE | I8: SE556207704901 | J8: =IF(NOT(ISBLANK($C8)),TRUE,"") -> TRUE | K8: {=IF(NOT(ISBLANK($C8)),AND(J8=TRUE,LEN(I8)<20,NOT(ISNUMBER(FIND('List of Values'!$C$2:$C$20,I8)))),"")} -> TRUE | L8: LILLÅSGATAN 3 | M8: =IF(NOT(ISBLANK($C8)),IF(NOT(ISBLANK(L8)),TRUE,FALSE),"") -> TRUE | N8: {=IF(NOT(ISBLANK($C8)),AND(M8=TRUE,LEN(L8)<81,NOT(ISNUMBER(FIND('List of Values'!$C$2:$C$20,L8)))),"")} -> TRUE | P8: =IF(NOT(ISBLANK($C8)),TRUE,"") -> TRUE | Q8: {=IF(NOT(ISBLANK($C8)),AND(P8=TRUE,LEN(O8)<81,NOT(ISNUMBER(FIND('List of Values'!$C$2:$C$20,O8)))),"")} -> TRUE | R8: VÄSTRA FRÖLUNDA | S8: =IF(NOT(ISBLANK($C8)),IF(NOT(ISBLANK(R8)),TRUE,FALSE),"") -> TRUE | T8: {=IF(NOT(ISBLANK($C8)),AND(S8=TRUE,LEN(R8)<61,NOT(ISNUMBER(FIND('List of Values'!$C$2:$C$23,R8)))),"")} -> TRUE | V8: =IF(NOT(ISBLANK($C8)),TRUE,"") -> TRUE | W8: {=IF(NOT(ISBLANK($C8)),AND(V8=TRUE,LEN(U8)<61,NOT(ISNUMBER(FIND('List of Values'!$C$2:$C$23,U8)))),"")} -> TRUE | X8: 426 77 | Y8: =IF(NOT(ISBLANK($C8)),IF(NOT(ISBLANK(X8)),TRUE,FALSE),"") -> TRUE | Z8: {=IF(NOT(ISBLANK($C8)),AND(Y8=TRUE,LEN(X8)<81,NOT(ISNUMBER(FIND('List of Values'!$C$2:$C$23,X8)))),"")} -> TRUE | AA8: SE | AB8: =IF(NOT(ISBLANK($C8)),IF(NOT(ISBLANK(AA8)),TRUE,FALSE),"") -> TRUE | AC8: =IF(NOT(ISBLANK($C8)),AND(AB8=TRUE,NOT(COUNTIF('List of Values'!$B$2:$B$255,AA8)=0)),"") -> TRUE | AD8: SEK | AE8: =IF(NOT(ISBLANK($C8)),IF(NOT(ISBLANK(AD8)),TRUE,FALSE),"") -> TRUE | AF8: =IF(NOT(ISBLANK($C8)),AND(AE8=TRUE,NOT(COUNTIF('List of Values'!$F$2:$F$255,AD8)=0)),"") -> TRUE | AG8: V_30NET | AH8: =IF(NOT(ISBLANK($C8)),IF(NOT(ISBLANK(AG8)),TRUE,FALSE),"") -> TRUE | AI8: =IF(NOT(ISBLANK($C8)),AND(AH8=TRUE,NOT(COUNTIF('List of Values'!$N$2:$N$40,AG8)=0)),"") -> TRUE | AJ8: V_BANK | AK8: =IF(NOT(ISBLANK($C8)),IF(NOT(ISBLANK(AJ8)),TRUE,FALSE),"") -> TRUE | AL8: =IF(NOT(ISBLANK($C8)),AND(AK8=TRUE,NOT(COUNTIF('List of Values'!$O$2:$O$30,AJ8)=0)),"") -> TRUE | AM8: S-DOM | AN8: =IF(NOT(ISBLANK($C8)),IF(NOT(ISBLANK(AM8)),TRUE,FALSE),"") -> TRUE | AO8: =IF(NOT(ISBLANK($C8)),AND(AN8=TRUE,NOT(COUNTIF('List of Values'!$AF$2:$AF$20,AM8)=0)),"") -> TRUE | AQ8: =IF(NOT(ISBLANK($C8)),TRUE,"") -> TRUE | AR8: {=IF(NOT(ISBLANK($C8)),AND(AQ8=TRUE,LEN(AP8)<81,NOT(ISNUMBER(FIND('List of Values'!$C$2:$C$20,AP8)))),"")} -> TRUE | AS8: =D8 -> SVENSKA INSJÖFISKARENAS AB | AT8: =IF(NOT(ISBLANK($C8)),IF(NOT(ISBLANK(AS8)),TRUE,FALSE),"") -> TRUE | AU8: {=IF(NOT(ISBLANK($C8)),AND(AT8=TRUE,LEN(AS8)<81,NOT(ISNUMBER(FIND('List of Values'!$C$2:$C$20,AS8)))),"")} -> TRUE | AV8: SVENSKAINSJÖFISKAREN | AW8: =IF(NOT(ISBLANK($C8)),IF(NOT(ISBLANK(AV8)),TRUE,FALSE),"") -> TRUE | AX8: {=IF(NOT(ISBLANK($C8)),AND(AW8=TRUE,LEN(AV8)<21,NOT(ISNUMBER(FIND('List of Values'!$C$2:$C$20,AV8)))),"")} -> TRUE | AY8: 14866 | AZ8: =IF(NOT(ISBLANK($C8)),IF(NOT(ISBLANK(AY8)),TRUE,FALSE),"") -> TRUE | BA8: =IF(NOT(ISBLANK($C8)),AND(AZ8=TRUE,NOT(COUNTIF('List of Values'!$R$2:$R$400,AY8)=0)),"") -> TRUE | BC8: =IF(NOT(ISBLANK($C8)),TRUE,"") -> TRUE | BD8: {=IF(NOT(ISBLANK($C8)),OR(ISBLANK(BB8),AND(NOT(ISNUMBER(FIND('List of Values'!$C$2:$C$23,BB8))),ISNUMBER(DATEVALUE(BB8)))),"")} -> TRUE | BF8: =IF(NOT(ISBLANK($C8)),TRUE,"") -> TRUE | BG8: {=IF(NOT(ISBLANK($C8)),OR(ISBLANK(BE8),AND(NOT(ISNUMBER(FIND('List of Values'!$C$2:$C$23,BE8))),ISNUMBER(DATEVALUE(BE8)))),"")} -> TRUE | BI8: =IF(NOT(ISBLANK($C8)),TRUE,"") -> TRUE | BJ8: =IF(NOT(ISBLANK($C8)),OR(ISBLANK(BH8),AND(LEN(BH8)<14,ISNUMBER(BH8))),"") -> TRUE | BK8: Invoice | BL8: =IF(NOT(ISBLANK($C8)),IF(NOT(ISBLANK(BK8)),TRUE,FALSE),"") -> TRUE | BM8: =IF(NOT(ISBLANK($C8)),AND(BL8=TRUE,NOT(COUNTIF('List of Values'!$A$2:$A$20,BK8)=0)),"") -> TRUE | BN8: Active | BO8: =IF(NOT(ISBLANK($C8)),IF(NOT(ISBLANK(BN8)),TRUE,FALSE),"") -> TRUE | BP8: =IF(NOT(ISBLANK($C8)),OR(BN8="active",BN8="delisted"),"") -> TRUE | BR8: =IF(NOT(ISBLANK($C8)),OR(AND($E8="intercompany",NOT(ISBLANK(BQ8))),AND(NOT($E8="intercompany"),ISBLANK(BQ8))),"") -> TRUE | BS8: =IF(NOT(ISBLANK($C8)),OR(ISBLANK(BQ8),NOT(COUNTIF('List of Values'!$K$2:$K$30,BQ8)=0)),"") -> TRUE | BU8: =IF(NOT(ISBLANK($C8)),TRUE,"") -> TRUE | BV8: =IF(NOT(ISBLANK($C8)),OR(ISBLANK(BT8),BT8="duty paid",BT8="bond"),"") -> TRUE | BX8: =IF(NOT(ISBLANK($C8)),TRUE,"") -> TRUE | BY8: =IF(NOT(ISBLANK($C8)),OR(ISBLANK(BW8),BW8="duty paid",BW8="bond"),"") -> TRUE | BZ8: =_xlfn.XLOOKUP(C8,[1]Blad1!$A:$A,[1]Blad1!$D:$D,"")
B9: =COUNTIF(C9:XFD9,"FALSE") -> 0 | C9: 218036 | D9: FÖRETAGARNA | E9: Indirect | F9: 5560933011 | G9: =IF(NOT(ISBLANK($C9)),IF(NOT(ISBLANK(F9)),TRUE,FALSE),"") -> TRUE | H9: {=IF(NOT(ISBLANK($C9)),AND(G9=TRUE,LEN(F9)<30,NOT(ISNUMBER(FIND('List of Values'!$C$2:$C$20,F9)))),"")} -> TRUE | I9: SE556093301101 | J9: =IF(NOT(ISBLANK($C9)),TRUE,"") -> TRUE | K9: {=IF(NOT(ISBLANK($C9)),AND(J9=TRUE,LEN(I9)<20,NOT(ISNUMBER(FIND('List of Values'!$C$2:$C$20,I9)))),"")} -> TRUE | L9: REGERINGSGATAN 52 | M9: =IF(NOT(ISBLANK($C9)),IF(NOT(ISBLANK(L9)),TRUE,FALSE),"") -> TRUE | N9: {=IF(NOT(ISBLANK($C9)),AND(M9=TRUE,LEN(L9)<81,NOT(ISNUMBER(FIND('List of Values'!$C$2:$C$20,L9)))),"")} -> TRUE | P9: =IF(NOT(ISBLANK($C9)),TRUE,"") -> TRUE | Q9: {=IF(NOT(ISBLANK($C9)),AND(P9=TRUE,LEN(O9)<81,NOT(ISNUMBER(FIND('List of Values'!$C$2:$C$20,O9)))),"")} -> TRUE | R9: STOCKHOLM | S9: =IF(NOT(ISBLANK($C9)),IF(NOT(ISBLANK(R9)),TRUE,FALSE),"") -> TRUE | T9: {=IF(NOT(ISBLANK($C9)),AND(S9=TRUE,LEN(R9)<61,NOT(ISNUMBER(FIND('List of Values'!$C$2:$C$23,R9)))),"")} -> TRUE | V9: =IF(NOT(ISBLANK($C9)),TRUE,"") -> TRUE | W9: {=IF(NOT(ISBLANK($C9)),AND(V9=TRUE,LEN(U9)<61,NOT(ISNUMBER(FIND('List of Values'!$C$2:$C$23,U9)))),"")} -> TRUE | X9: 106 67 | Y9: =IF(NOT(ISBLANK($C9)),IF(NOT(ISBLANK(X9)),TRUE,FALSE),"") -> TRUE | Z9: {=IF(NOT(ISBLANK($C9)),AND(Y9=TRUE,LEN(X9)<81,NOT(ISNUMBER(FIND('List of Values'!$C$2:$C$23,X9)))),"")} -> TRUE | AA9: SE | AB9: =IF(NOT(ISBLANK($C9)),IF(NOT(ISBLANK(AA9)),TRUE,FALSE),"") -> TRUE | AC9: =IF(NOT(ISBLANK($C9)),AND(AB9=TRUE,NOT(COUNTIF('List of Values'!$B$2:$B$255,AA9)=0)),"") -> TRUE | AD9: SEK | AE9: =IF(NOT(ISBLANK($C9)),IF(NOT(ISBLANK(AD9)),TRUE,FALSE),"") -> TRUE | AF9: =IF(NOT(ISBLANK($C9)),AND(AE9=TRUE,NOT(COUNTIF('List of Values'!$F$2:$F$255,AD9)=0)),"") -> TRUE | AG9: V_10EOM | AH9: =IF(NOT(ISBLANK($C9)),IF(NOT(ISBLANK(AG9)),TRUE,FALSE),"") -> TRUE | AI9: =IF(NOT(ISBLANK($C9)),AND(AH9=TRUE,NOT(COUNTIF('List of Values'!$N$2:$N$40,AG9)=0)),"") -> TRUE | AJ9: V_BANK | AK9: =IF(NOT(ISBLANK($C9)),IF(NOT(ISBLANK(AJ9)),TRUE,FALSE),"") -> TRUE | AL9: =IF(NOT(ISBLANK($C9)),AND(AK9=TRUE,NOT(COUNTIF('List of Values'!$O$2:$O$30,AJ9)=0)),"") -> TRUE | AM9: S-DOM | AN9: =IF(NOT(ISBLANK($C9)),IF(NOT(ISBLANK(AM9)),TRUE,FALSE),"") -> TRUE | AO9: =IF(NOT(ISBLANK($C9)),AND(AN9=TRUE,NOT(COUNTIF('List of Values'!$AF$2:$AF$20,AM9)=0)),"") -> TRUE | AQ9: =IF(NOT(ISBLANK($C9)),TRUE,"") -> TRUE | AR9: {=IF(NOT(ISBLANK($C9)),AND(AQ9=TRUE,LEN(AP9)<81,NOT(ISNUMBER(FIND('List of Values'!$C$2:$C$20,AP9)))),"")} -> TRUE | AS9: =D9 -> FÖRETAGARNA | AT9: =IF(NOT(ISBLANK($C9)),IF(NOT(ISBLANK(AS9)),TRUE,FALSE),"") -> TRUE | AU9: {=IF(NOT(ISBLANK($C9)),AND(AT9=TRUE,LEN(AS9)<81,NOT(ISNUMBER(FIND('List of Values'!$C$2:$C$20,AS9)))),"")} -> TRUE | AV9: FÖRETAGARNA | AW9: =IF(NOT(ISBLANK($C9)),IF(NOT(ISBLANK(AV9)),TRUE,FALSE),"") -> TRUE | AX9: {=IF(NOT(ISBLANK($C9)),AND(AW9=TRUE,LEN(AV9)<21,NOT(ISNUMBER(FIND('List of Values'!$C$2:$C$20,AV9)))),"")} -> TRUE | AY9: 10001 | AZ9: =IF(NOT(ISBLANK($C9)),TRUE,"") -> TRUE | BA9: =IF(NOT(ISBLANK($C9)),AND(AZ9=TRUE,NOT(COUNTIF('List of Values'!$R$2:$R$400,AY9)=0)),"") -> TRUE | BC9: =IF(NOT(ISBLANK($C9)),TRUE,"") -> TRUE | BD9: {=IF(NOT(ISBLANK($C9)),OR(ISBLANK(BB9),AND(NOT(ISNUMBER(FIND('List of Values'!$C$2:$C$23,BB9))),ISNUMBER(DATEVALUE(BB9)))),"")} -> TRUE | BF9: =IF(NOT(ISBLANK($C9)),TRUE,"") -> TRUE | BG9: {=IF(NOT(ISBLANK($C9)),OR(ISBLANK(BE9),AND(NOT(ISNUMBER(FIND('List of Values'!$C$2:$C$23,BE9))),ISNUMBER(DATEVALUE(BE9)))),"")} -> TRUE | BI9: =IF(NOT(ISBLANK($C9)),TRUE,"") -> TRUE | BJ9: =IF(NOT(ISBLANK($C9)),OR(ISBLANK(BH9),AND(LEN(BH9)<14,ISNUMBER(BH9))),"") -> TRUE | BK9: Invoice | BL9: =IF(NOT(ISBLANK($C9)),IF(NOT(ISBLANK(BK9)),TRUE,FALSE),"") -> TRUE | BM9: =IF(NOT(ISBLANK($C9)),AND(BL9=TRUE,NOT(COUNTIF('List of Values'!$A$2:$A$20,BK9)=0)),"") -> TRUE | BN9: Active | BO9: =IF(NOT(ISBLANK($C9)),IF(NOT(ISBLANK(BN9)),TRUE,FALSE),"") -> TRUE | BP9: =IF(NOT(ISBLANK($C9)),OR(BN9="active",BN9="delisted"),"") -> TRUE | BR9: =IF(NOT(ISBLANK($C9)),OR(AND($E9="intercompany",NOT(ISBLANK(BQ9))),AND(NOT($E9="intercompany"),ISBLANK(BQ9))),"") -> TRUE | BS9: =IF(NOT(ISBLANK($C9)),OR(ISBLANK(BQ9),NOT(COUNTIF('List of Values'!$K$2:$K$30,BQ9)=0)),"") -> TRUE | BU9: =IF(NOT(ISBLANK($C9)),TRUE,"") -> TRUE | BV9: =IF(NOT(ISBLANK($C9)),OR(ISBLANK(BT9),BT9="duty paid",BT9="bond"),"") -> TRUE | BX9: =IF(NOT(ISBLANK($C9)),TRUE,"") -> TRUE | BY9: =IF(NOT(ISBLANK($C9)),OR(ISBLANK(BW9),BW9="duty paid",BW9="bond"),"") -> TRUE | BZ9: =_xlfn.XLOOKUP(C9,[1]Blad1!$A:$A,[1]Blad1!$D:$D,"")
B10: =COUNTIF(C10:XFD10,"FALSE") -> 0 | C10: 217965 | D10: HAVETS SKAFFERI I KODE AB | E10: Trade | F10: 5567081319 | G10: =IF(NOT(ISBLANK($C10)),IF(NOT(ISBLANK(F10)),TRUE,FALSE),"") -> TRUE | H10: {=IF(NOT(ISBLANK($C10)),AND(G10=TRUE,LEN(F10)<30,NOT(ISNUMBER(FIND('List of Values'!$C$2:$C$20,F10)))),"")} -> TRUE | I10: SE556708131901 | J10: =IF(NOT(ISBLANK($C10)),TRUE,"") -> TRUE | K10: {=IF(NOT(ISBLANK($C10)),AND(J10=TRUE,LEN(I10)<20,NOT(ISNUMBER(FIND('List of Values'!$C$2:$C$20,I10)))),"")} -> TRUE | L10: FISKHAMNEN PIRHUS 1 | M10: =IF(NOT(ISBLANK($C10)),IF(NOT(ISBLANK(L10)),TRUE,FALSE),"") -> TRUE | N10: {=IF(NOT(ISBLANK($C10)),AND(M10=TRUE,LEN(L10)<81,NOT(ISNUMBER(FIND('List of Values'!$C$2:$C$20,L10)))),"")} -> TRUE | P10: =IF(NOT(ISBLANK($C10)),TRUE,"") -> TRUE | Q10: {=IF(NOT(ISBLANK($C10)),AND(P10=TRUE,LEN(O10)<81,NOT(ISNUMBER(FIND('List of Values'!$C$2:$C$20,O10)))),"")} -> TRUE | R10: GÖTEBORG | S10: =IF(NOT(ISBLANK($C10)),IF(NOT(ISBLANK(R10)),TRUE,FALSE),"") -> TRUE | T10: {=IF(NOT(ISBLANK($C10)),AND(S10=TRUE,LEN(R10)<61,NOT(ISNUMBER(FIND('List of Values'!$C$2:$C$23,R10)))),"")} -> TRUE | V10: =IF(NOT(ISBLANK($C10)),TRUE,"") -> TRUE | W10: {=IF(NOT(ISBLANK($C10)),AND(V10=TRUE,LEN(U10)<61,NOT(ISNUMBER(FIND('List of Values'!$C$2:$C$23,U10)))),"")} -> TRUE | X10: 414 58 | Y10: =IF(NOT(ISBLANK($C10)),IF(NOT(ISBLANK(X10)),TRUE,FALSE),"") -> TRUE | Z10: {=IF(NOT(ISBLANK($C10)),AND(Y10=TRUE,LEN(X10)<81,NOT(ISNUMBER(FIND('List of Values'!$C$2:$C$23,X10)))),"")} -> TRUE | AA10: SE | AB10: =IF(NOT(ISBLANK($C10)),IF(NOT(ISBLANK(AA10)),TRUE,FALSE),"") -> TRUE | AC10: =IF(NOT(ISBLANK($C10)),AND(AB10=TRUE,NOT(COUNTIF('List of Values'!$B$2:$B$255,AA10)=0)),"") -> TRUE | AD10: SEK | AE10: =IF(NOT(ISBLANK($C10)),IF(NOT(ISBLANK(AD10)),TRUE,FALSE),"") -> TRUE | AF10: =IF(NOT(ISBLANK($C10)),AND(AE10=TRUE,NOT(COUNTIF('List of Values'!$F$2:$F$255,AD10)=0)),"") -> TRUE | AG10: V_10EOM | AH10: =IF(NOT(ISBLANK($C10)),IF(NOT(ISBLANK(AG10)),TRUE,FALSE),"") -> TRUE | AI10: =IF(NOT(ISBLANK($C10)),AND(AH10=TRUE,NOT(COUNTIF('List of Values'!$N$2:$N$40,AG10)=0)),"") -> TRUE | AJ10: V_BANK | AK10: =IF(NOT(ISBLANK($C10)),IF(NOT(ISBLANK(AJ10)),TRUE,FALSE),"") -> TRUE | AL10: =IF(NOT(ISBLANK($C10)),AND(AK10=TRUE,NOT(COUNTIF('List of Values'!$O$2:$O$30,AJ10)=0)),"") -> TRUE | AM10: S-DOM | AN10: =IF(NOT(ISBLANK($C10)),IF(NOT(ISBLANK(AM10)),TRUE,FALSE),"") -> TRUE | AO10: =IF(NOT(ISBLANK($C10)),AND(AN10=TRUE,NOT(COUNTIF('List of Values'!$AF$2:$AF$20,AM10)=0)),"") -> TRUE | AQ10: =IF(NOT(ISBLANK($C10)),TRUE,"") -> TRUE | AR10: {=IF(NOT(ISBLANK($C10)),AND(AQ10=TRUE,LEN(AP10)<81,NOT(ISNUMBER(FIND('List of Values'!$C$2:$C$20,AP10)))),"")} -> TRUE | AS10: =D10 -> HAVETS SKAFFERI I KODE AB | AT10: =IF(NOT(ISBLANK($C10)),IF(NOT(ISBLANK(AS10)),TRUE,FALSE),"") -> TRUE | AU10: {=IF(NOT(ISBLANK($C10)),AND(AT10=TRUE,LEN(AS10)<81,NOT(ISNUMBER(FIND('List of Values'!$C$2:$C$20,AS10)))),"")} -> TRUE | AV10: HAVETSSKAFFERIIKODEA | AW10: =IF(NOT(ISBLANK($C10)),IF(NOT(ISBLANK(AV10)),TRUE,FALSE),"") -> TRUE | AX10: {=IF(NOT(ISBLANK($C10)),AND(AW10=TRUE,LEN(AV10)<21,NOT(ISNUMBER(FIND('List of Values'!$C$2:$C$20,AV10)))),"")} -> TRUE | AY10: 12418 | AZ10: =IF(NOT(ISBLANK($C10)),TRUE,"") -> TRUE | BA10: =IF(NOT(ISBLANK($C10)),AND(AZ10=TRUE,NOT(COUNTIF('List of Values'!$R$2:$R$400,AY10)=0)),"") -> TRUE | BC10: =IF(NOT(ISBLANK($C10)),TRUE,"") -> TRUE | BD10: {=IF(NOT(ISBLANK($C10)),OR(ISBLANK(BB10),AND(NOT(ISNUMBER(FIND('List of Values'!$C$2:$C$23,BB10))),ISNUMBER(DATEVALUE(BB10)))),"")} -> TRUE | BF10: =IF(NOT(ISBLANK($C10)),TRUE,"") -> TRUE | BG10: {=IF(NOT(ISBLANK($C10)),OR(ISBLANK(BE10),AND(NOT(ISNUMBER(FIND('List of Values'!$C$2:$C$23,BE10))),ISNUMBER(DATEVALUE(BE10)))),"")} -> TRUE | BI10: =IF(NOT(ISBLANK($C10)),TRUE,"") -> TRUE | BJ10: =IF(NOT(ISBLANK($C10)),OR(ISBLANK(BH10),AND(LEN(BH10)<14,ISNUMBER(BH10))),"") -> TRUE | BK10: Invoice | BL10: =IF(NOT(ISBLANK($C10)),IF(NOT(ISBLANK(BK10)),TRUE,FALSE),"") -> TRUE | BM10: =IF(NOT(ISBLANK($C10)),AND(BL10=TRUE,NOT(COUNTIF('List of Values'!$A$2:$A$20,BK10)=0)),"") -> TRUE | BN10: Active | BO10: =IF(NOT(ISBLANK($C10)),IF(NOT(ISBLANK(BN10)),TRUE,FALSE),"") -> TRUE | BP10: =IF(NOT(ISBLANK($C10)),OR(BN10="active",BN10="delisted"),"") -> TRUE | BR10: =IF(NOT(ISBLANK($C10)),OR(AND($E10="intercompany",NOT(ISBLANK(BQ10))),AND(NOT($E10="intercompany"),ISBLANK(BQ10))),"") -> TRUE | BS10: =IF(NOT(ISBLANK($C10)),OR(ISBLANK(BQ10),NOT(COUNTIF('List of Values'!$K$2:$K$30,BQ10)=0)),"") -> TRUE | BU10: =IF(NOT(ISBLANK($C10)),TRUE,"") -> TRUE | BV10: =IF(NOT(ISBLANK($C10)),OR(ISBLANK(BT10),BT10="duty paid",BT10="bond"),"") -> TRUE | BX10: =IF(NOT(ISBLANK($C10)),TRUE,"") -> TRUE | BY10: =IF(NOT(ISBLANK($C10)),OR(ISBLANK(BW10),BW10="duty paid",BW10="bond"),"") -> TRUE | BZ10: =_xlfn.XLOOKUP(C10,[1]Blad1!$A:$A,[1]Blad1!$D:$D,"")
B11: =COUNTIF(C11:XFD11,"FALSE") -> 0 | C11: 218285 | D11: EKO MUSSLOR P.A.C AB | E11: Trade | F11: 5568028244 | G11: =IF(NOT(ISBLANK($C11)),IF(NOT(ISBLANK(F11)),TRUE,FALSE),"") -> TRUE | H11: {=IF(NOT(ISBLANK($C11)),AND(G11=TRUE,LEN(F11)<30,NOT(ISNUMBER(FIND('List of Values'!$C$2:$C$20,F11)))),"")} -> TRUE | I11: SE556802824401 | J11: =IF(NOT(ISBLANK($C11)),TRUE,"") -> TRUE | K11: {=IF(NOT(ISBLANK($C11)),AND(J11=TRUE,LEN(I11)<20,NOT(ISNUMBER(FIND('List of Values'!$C$2:$C$20,I11)))),"")} -> TRUE | L11: RINGÖGATAN 33 | M11: =IF(NOT(ISBLANK($C11)),IF(NOT(ISBLANK(L11)),TRUE,FALSE),"") -> TRUE | N11: {=IF(NOT(ISBLANK($C11)),AND(M11=TRUE,LEN(L11)<81,NOT(ISNUMBER(FIND('List of Values'!$C$2:$C$20,L11)))),"")} -> TRUE | P11: =IF(NOT(ISBLANK($C11)),TRUE,"") -> TRUE | Q11: {=IF(NOT(ISBLANK($C11)),AND(P11=TRUE,LEN(O11)<81,NOT(ISNUMBER(FIND('List of Values'!$C$2:$C$20,O11)))),"")} -> TRUE | R11: GÖTEBORG | S11: =IF(NOT(ISBLANK($C11)),IF(NOT(ISBLANK(R11)),TRUE,FALSE),"") -> TRUE | T11: {=IF(NOT(ISBLANK($C11)),AND(S11=TRUE,LEN(R11)<61,NOT(ISNUMBER(FIND('List of Values'!$C$2:$C$23,R11)))),"")} -> TRUE | V11: =IF(NOT(ISBLANK($C11)),TRUE,"") -> TRUE | W11: {=IF(NOT(ISBLANK($C11)),AND(V11=TRUE,LEN(U11)<61,NOT(ISNUMBER(FIND('List of Values'!$C$2:$C$23,U11)))),"")} -> TRUE | X11: 417 07 | Y11: =IF(NOT(ISBLANK($C11)),IF(NOT(ISBLANK(X11)),TRUE,FALSE),"") -> TRUE | Z11: {=IF(NOT(ISBLANK($C11)),AND(Y11=TRUE,LEN(X11)<81,NOT(ISNUMBER(FIND('List of Values'!$C$2:$C$23,X11)))),"")} -> TRUE | AA11: SE | AB11: =IF(NOT(ISBLANK($C11)),IF(NOT(ISBLANK(AA11)),TRUE,FALSE),"") -> TRUE | AC11: =IF(NOT(ISBLANK($C11)),AND(AB11=TRUE,NOT(COUNTIF('List of Values'!$B$2:$B$255,AA11)=0)),"") -> TRUE | AD11: SEK | AE11: =IF(NOT(ISBLANK($C11)),IF(NOT(ISBLANK(AD11)),TRUE,FALSE),"") -> TRUE | AF11: =IF(NOT(ISBLANK($C11)),AND(AE11=TRUE,NOT(COUNTIF('List of Values'!$F$2:$F$255,AD11)=0)),"") -> TRUE | AG11: V_20NET | AH11: =IF(NOT(ISBLANK($C11)),IF(NOT(ISBLANK(AG11)),TRUE,FALSE),"") -> TRUE | AI11: =IF(NOT(ISBLANK($C11)),AND(AH11=TRUE,NOT(COUNTIF('List of Values'!$N$2:$N$40,AG11)=0)),"") -> TRUE | AJ11: V_BANK | AK11: =IF(NOT(ISBLANK($C11)),IF(NOT(ISBLANK(AJ11)),TRUE,FALSE),"") -> TRUE | AL11: =IF(NOT(ISBLANK($C11)),AND(AK11=TRUE,NOT(COUNTIF('List of Values'!$O$2:$O$30,AJ11)=0)),"") -> TRUE | AM11: S-DOM | AN11: =IF(NOT(ISBLANK($C11)),IF(NOT(ISBLANK(AM11)),TRUE,FALSE),"") -> TRUE | AO11: =IF(NOT(ISBLANK($C11)),AND(AN11=TRUE,NOT(COUNTIF('List of Values'!$AF$2:$AF$20,AM11)=0)),"") -> TRUE | AQ11: =IF(NOT(ISBLANK($C11)),TRUE,"") -> TRUE | AR11: {=IF(NOT(ISBLANK($C11)),AND(AQ11=TRUE,LEN(AP11)<81,NOT(ISNUMBER(FIND('List of Values'!$C$2:$C$20,AP11)))),"")} -> TRUE | AS11: =D11 -> EKO MUSSLOR P.A.C AB | AT11: =IF(NOT(ISBLANK($C11)),IF(NOT(ISBLANK(AS11)),TRUE,FALSE),"") -> TRUE | AU11: {=IF(NOT(ISBLANK($C11)),AND(AT11=TRUE,LEN(AS11)<81,NOT(ISNUMBER(FIND('List of Values'!$C$2:$C$20,AS11)))),"")} -> TRUE | AV11: EKOMUSSLORP.A.CAB | AW11: =IF(NOT(ISBLANK($C11)),IF(NOT(ISBLANK(AV11)),TRUE,FALSE),"") -> TRUE | AX11: {=IF(NOT(ISBLANK($C11)),AND(AW11=TRUE,LEN(AV11)<21,NOT(ISNUMBER(FIND('List of Values'!$C$2:$C$20,AV11)))),"")} -> TRUE | AY11: 11667 | AZ11: =IF(NOT(ISBLANK($C11)),TRUE,"") -> TRUE | BA11: =IF(NOT(ISBLANK($C11)),AND(AZ11=TRUE,NOT(COUNTIF('List of Values'!$R$2:$R$400,AY11)=0)),"") -> TRUE | BC11: =IF(NOT(ISBLANK($C11)),TRUE,"") -> TRUE | BD11: {=IF(NOT(ISBLANK($C11)),OR(ISBLANK(BB11),AND(NOT(ISNUMBER(FIND('List of Values'!$C$2:$C$23,BB11))),ISNUMBER(DATEVALUE(BB11)))),"")} -> TRUE | BF11: =IF(NOT(ISBLANK($C11)),TRUE,"") -> TRUE | BG11: {=IF(NOT(ISBLANK($C11)),OR(ISBLANK(BE11),AND(NOT(ISNUMBER(FIND('List of Values'!$C$2:$C$23,BE11))),ISNUMBER(DATEVALUE(BE11)))),"")} -> TRUE | BI11: =IF(NOT(ISBLANK($C11)),TRUE,"") -> TRUE | BJ11: =IF(NOT(ISBLANK($C11)),OR(ISBLANK(BH11),AND(LEN(BH11)<14,ISNUMBER(BH11))),"") -> TRUE | BK11: Invoice | BL11: =IF(NOT(ISBLANK($C11)),IF(NOT(ISBLANK(BK11)),TRUE,FALSE),"") -> TRUE | BM11: =IF(NOT(ISBLANK($C11)),AND(BL11=TRUE,NOT(COUNTIF('List of Values'!$A$2:$A$20,BK11)=0)),"") -> TRUE | BN11: Active | BO11: =IF(NOT(ISBLANK($C11)),IF(NOT(ISBLANK(BN11)),TRUE,FALSE),"") -> TRUE | BP11: =IF(NOT(ISBLANK($C11)),OR(BN11="active",BN11="delisted"),"") -> TRUE | BR11: =IF(NOT(ISBLANK($C11)),OR(AND($E11="intercompany",NOT(ISBLANK(BQ11))),AND(NOT($E11="intercompany"),ISBLANK(BQ11))),"") -> TRUE | BS11: =IF(NOT(ISBLANK($C11)),OR(ISBLANK(BQ11),NOT(COUNTIF('List of Values'!$K$2:$K$30,BQ11)=0)),"") -> TRUE | BU11: =IF(NOT(ISBLANK($C11)),TRUE,"") -> TRUE | BV11: =IF(NOT(ISBLANK($C11)),OR(ISBLANK(BT11),BT11="duty paid",BT11="bond"),"") -> TRUE | BX11: =IF(NOT(ISBLANK($C11)),TRUE,"") -> TRUE | BY11: =IF(NOT(ISBLANK($C11)),OR(ISBLANK(BW11),BW11="duty paid",BW11="bond"),"") -> TRUE | BZ11: =_xlfn.XLOOKUP(C11,[1]Blad1!$A:$A,[1]Blad1!$D:$D,"") -> x
B12: =COUNTIF(C12:XFD12,"FALSE") -> 0 | C12: 218038 | D12: REMONDIS SWEDEN AB | E12: Indirect | F12: 5561142810 | G12: =IF(NOT(ISBLANK($C12)),IF(NOT(ISBLANK(F12)),TRUE,FALSE),"") -> TRUE | H12: {=IF(NOT(ISBLANK($C12)),AND(G12=TRUE,LEN(F12)<30,NOT(ISNUMBER(FIND('List of Values'!$C$2:$C$20,F12)))),"")} -> TRUE | I12: SE556114281001 | J12: =IF(NOT(ISBLANK($C12)),TRUE,"") -> TRUE | K12: {=IF(NOT(ISBLANK($C12)),AND(J12=TRUE,LEN(I12)<20,NOT(ISNUMBER(FIND('List of Values'!$C$2:$C$20,I12)))),"")} -> TRUE | L12: IMPORTGATAN 45 | M12: =IF(NOT(ISBLANK($C12)),IF(NOT(ISBLANK(L12)),TRUE,FALSE),"") -> TRUE | N12: {=IF(NOT(ISBLANK($C12)),AND(M12=TRUE,LEN(L12)<81,NOT(ISNUMBER(FIND('List of Values'!$C$2:$C$20,L12)))),"")} -> TRUE | P12: =IF(NOT(ISBLANK($C12)),TRUE,"") -> TRUE | Q12: {=IF(NOT(ISBLANK($C12)),AND(P12=TRUE,LEN(O12)<81,NOT(ISNUMBER(FIND('List of Values'!$C$2:$C$20,O12)))),"")} -> TRUE | R12: HISINGS BACKA | S12: =IF(NOT(ISBLANK($C12)),IF(NOT(ISBLANK(R12)),TRUE,FALSE),"") -> TRUE | T12: {=IF(NOT(ISBLANK($C12)),AND(S12=TRUE,LEN(R12)<61,NOT(ISNUMBER(FIND('List of Values'!$C$2:$C$23,R12)))),"")} -> TRUE | V12: =IF(NOT(ISBLANK($C12)),TRUE,"") -> TRUE | W12: {=IF(NOT(ISBLANK($C12)),AND(V12=TRUE,LEN(U12)<61,NOT(ISNUMBER(FIND('List of Values'!$C$2:$C$23,U12)))),"")} -> TRUE | X12: 422 46 | Y12: =IF(NOT(ISBLANK($C12)),IF(NOT(ISBLANK(X12)),TRUE,FALSE),"") -> TRUE | Z12: {=IF(NOT(ISBLANK($C12)),AND(Y12=TRUE,LEN(X12)<81,NOT(ISNUMBER(FIND('List of Values'!$C$2:$C$23,X12)))),"")} -> TRUE | AA12: SE | AB12: =IF(NOT(ISBLANK($C12)),IF(NOT(ISBLANK(AA12)),TRUE,FALSE),"") -> TRUE | AC12: =IF(NOT(ISBLANK($C12)),AND(AB12=TRUE,NOT(COUNTIF('List of Values'!$B$2:$B$255,AA12)=0)),"") -> TRUE | AD12: SEK | AE12: =IF(NOT(ISBLANK($C12)),IF(NOT(ISBLANK(AD12)),TRUE,FALSE),"") -> TRUE | AF12: =IF(NOT(ISBLANK($C12)),AND(AE12=TRUE,NOT(COUNTIF('List of Values'!$F$2:$F$255,AD12)=0)),"") -> TRUE | AG12: V_20NET | AH12: =IF(NOT(ISBLANK($C12)),IF(NOT(ISBLANK(AG12)),TRUE,FALSE),"") -> TRUE | AI12: =IF(NOT(ISBLANK($C12)),AND(AH12=TRUE,NOT(COUNTIF('List of Values'!$N$2:$N$40,AG12)=0)),"") -> TRUE | AJ12: V_BANK | AK12: =IF(NOT(ISBLANK($C12)),IF(NOT(ISBLANK(AJ12)),TRUE,FALSE),"") -> TRUE | AL12: =IF(NOT(ISBLANK($C12)),AND(AK12=TRUE,NOT(COUNTIF('List of Values'!$O$2:$O$30,AJ12)=0)),"") -> TRUE | AM12: S-DOM | AN12: =IF(NOT(ISBLANK($C12)),IF(NOT(ISBLANK(AM12)),TRUE,FALSE),"") -> TRUE | AO12: =IF(NOT(ISBLANK($C12)),AND(AN12=TRUE,NOT(COUNTIF('List of Values'!$AF$2:$AF$20,AM12)=0)),"") -> TRUE | AQ12: =IF(NOT(ISBLANK($C12)),TRUE,"") -> TRUE | AR12: {=IF(NOT(ISBLANK($C12)),AND(AQ12=TRUE,LEN(AP12)<81,NOT(ISNUMBER(FIND('List of Values'!$C$2:$C$20,AP12)))),"")} -> TRUE | AS12: =D12 -> REMONDIS SWEDEN AB | AT12: =IF(NOT(ISBLANK($C12)),IF(NOT(ISBLANK(AS12)),TRUE,FALSE),"") -> TRUE | AU12: {=IF(NOT(ISBLANK($C12)),AND(AT12=TRUE,LEN(AS12)<81,NOT(ISNUMBER(FIND('List of Values'!$C$2:$C$20,AS12)))),"")} -> TRUE | AV12: REMONDISSWEDENAB | AW12: =IF(NOT(ISBLANK($C12)),IF(NOT(ISBLANK(AV12)),TRUE,FALSE),"") -> TRUE | AX12: {=IF(NOT(ISBLANK($C12)),AND(AW12=TRUE,LEN(AV12)<21,NOT(ISNUMBER(FIND('List of Values'!$C$2:$C$20,AV12)))),"")} -> TRUE | AY12: 10001 | AZ12: =IF(NOT(ISBLANK($C12)),TRUE,"") -> TRUE | BA12: =IF(NOT(ISBLANK($C12)),AND(AZ12=TRUE,NOT(COUNTIF('List of Values'!$R$2:$R$400,AY12)=0)),"") -> TRUE | BC12: =IF(NOT(ISBLANK($C12)),TRUE,"") -> TRUE | BD12: {=IF(NOT(ISBLANK($C12)),OR(ISBLANK(BB12),AND(NOT(ISNUMBER(FIND('List of Values'!$C$2:$C$23,BB12))),ISNUMBER(DATEVALUE(BB12)))),"")} -> TRUE | BF12: =IF(NOT(ISBLANK($C12)),TRUE,"") -> TRUE | BG12: {=IF(NOT(ISBLANK($C12)),OR(ISBLANK(BE12),AND(NOT(ISNUMBER(FIND('List of Values'!$C$2:$C$23,BE12))),ISNUMBER(DATEVALUE(BE12)))),"")} -> TRUE | BI12: =IF(NOT(ISBLANK($C12)),TRUE,"") -> TRUE | BJ12: =IF(NOT(ISBLANK($C12)),OR(ISBLANK(BH12),AND(LEN(BH12)<14,ISNUMBER(BH12))),"") -> TRUE | BK12: Invoice | BL12: =IF(NOT(ISBLANK($C12)),IF(NOT(ISBLANK(BK12)),TRUE,FALSE),"") -> TRUE | BM12: =IF(NOT(ISBLANK($C12)),AND(BL12=TRUE,NOT(COUNTIF('List of Values'!$A$2:$A$20,BK12)=0)),"") -> TRUE | BN12: Active | BO12: =IF(NOT(ISBLANK($C12)),IF(NOT(ISBLANK(BN12)),TRUE,FALSE),"") -> TRUE | BP12: =IF(NOT(ISBLANK($C12)),OR(BN12="active",BN12="delisted"),"") -> TRUE | BR12: =IF(NOT(ISBLANK($C12)),OR(AND($E12="intercompany",NOT(ISBLANK(BQ12))),AND(NOT($E12="intercompany"),ISBLANK(BQ12))),"") -> TRUE | BS12: =IF(NOT(ISBLANK($C12)),OR(ISBLANK(BQ12),NOT(COUNTIF('List of Values'!$K$2:$K$30,BQ12)=0)),"") -> TRUE | BU12: =IF(NOT(ISBLANK($C12)),TRUE,"") -> TRUE | BV12: =IF(NOT(ISBLANK($C12)),OR(ISBLANK(BT12),BT12="duty paid",BT12="bond"),"") -> TRUE | BX12: =IF(NOT(ISBLANK($C12)),TRUE,"") -> TRUE | BY12: =IF(NOT(ISBLANK($C12)),OR(ISBLANK(BW12),BW12="duty paid",BW12="bond"),"") -> TRUE | BZ12: =_xlfn.XLOOKUP(C12,[1]Blad1!$A:$A,[1]Blad1!$D:$D,"")
B13: =COUNTIF(C13:XFD13,"FALSE") -> 0 | C13: 218053 | D13: FIRESAFE SVERIGE AB | E13: Indirect | F13: 5562629260 | G13: =IF(NOT(ISBLANK($C13)),IF(NOT(ISBLANK(F13)),TRUE,FALSE),"") -> TRUE | H13: {=IF(NOT(ISBLANK($C13)),AND(G13=TRUE,LEN(F13)<30,NOT(ISNUMBER(FIND('List of Values'!$C$2:$C$20,F13)))),"")} -> TRUE | I13: SE556262926001 | J13: =IF(NOT(ISBLANK($C13)),TRUE,"") -> TRUE | K13: {=IF(NOT(ISBLANK($C13)),AND(J13=TRUE,LEN(I13)<20,NOT(ISNUMBER(FIND('List of Values'!$C$2:$C$20,I13)))),"")} -> TRUE | L13: BOX 32050 | M13: =IF(NOT(ISBLANK($C13)),IF(NOT(ISBLANK(L13)),TRUE,FALSE),"") -> TRUE | N13: {=IF(NOT(ISBLANK($C13)),AND(M13=TRUE,LEN(L13)<81,NOT(ISNUMBER(FIND('List of Values'!$C$2:$C$20,L13)))),"")} -> TRUE | P13: =IF(NOT(ISBLANK($C13)),TRUE,"") -> TRUE | Q13: {=IF(NOT(ISBLANK($C13)),AND(P13=TRUE,LEN(O13)<81,NOT(ISNUMBER(FIND('List of Values'!$C$2:$C$20,O13)))),"")} -> TRUE | R13: STOCKHOLM | S13: =IF(NOT(ISBLANK($C13)),IF(NOT(ISBLANK(R13)),TRUE,FALSE),"") -> TRUE | T13: {=IF(NOT(ISBLANK($C13)),AND(S13=TRUE,LEN(R13)<61,NOT(ISNUMBER(FIND('List of Values'!$C$2:$C$23,R13)))),"")} -> TRUE | V13: =IF(NOT(ISBLANK($C13)),TRUE,"") -> TRUE | W13: {=IF(NOT(ISBLANK($C13)),AND(V13=TRUE,LEN(U13)<61,NOT(ISNUMBER(FIND('List of Values'!$C$2:$C$23,U13)))),"")} -> TRUE | X13: 126 11 | Y13: =IF(NOT(ISBLANK($C13)),IF(NOT(ISBLANK(X13)),TRUE,FALSE),"") -> TRUE | Z13: {=IF(NOT(ISBLANK($C13)),AND(Y13=TRUE,LEN(X13)<81,NOT(ISNUMBER(FIND('List of Values'!$C$2:$C$23,X13)))),"")} -> TRUE | AA13: SE | AB13: =IF(NOT(ISBLANK($C13)),IF(NOT(ISBLANK(AA13)),TRUE,FALSE),"") -> TRUE | AC13: =IF(NOT(ISBLANK($C13)),AND(AB13=TRUE,NOT(COUNTIF('List of Values'!$B$2:$B$255,AA13)=0)),"") -> TRUE | AD13: SEK | AE13: =IF(NOT(ISBLANK($C13)),IF(NOT(ISBLANK(AD13)),TRUE,FALSE),"") -> TRUE | AF13: =IF(NOT(ISBLANK($C13)),AND(AE13=TRUE,NOT(COUNTIF('List of Values'!$F$2:$F$255,AD13)=0)),"") -> TRUE | AG13: V_20NET | AH13: =IF(NOT(ISBLANK($C13)),IF(NOT(ISBLANK(AG13)),TRUE,FALSE),"") -> TRUE | AI13: =IF(NOT(ISBLANK($C13)),AND(AH13=TRUE,NOT(COUNTIF('List of Values'!$N$2:$N$40,AG13)=0)),"") -> TRUE | AJ13: V_BANK | AK13: =IF(NOT(ISBLANK($C13)),IF(NOT(ISBLANK(AJ13)),TRUE,FALSE),"") -> TRUE | AL13: =IF(NOT(ISBLANK($C13)),AND(AK13=TRUE,NOT(COUNTIF('List of Values'!$O$2:$O$30,AJ13)=0)),"") -> TRUE | AM13: S-DOM | AN13: =IF(NOT(ISBLANK($C13)),IF(NOT(ISBLANK(AM13)),TRUE,FALSE),"") -> TRUE | AO13: =IF(NOT(ISBLANK($C13)),AND(AN13=TRUE,NOT(COUNTIF('List of Values'!$AF$2:$AF$20,AM13)=0)),"") -> TRUE | AQ13: =IF(NOT(ISBLANK($C13)),TRUE,"") -> TRUE | AR13: {=IF(NOT(ISBLANK($C13)),AND(AQ13=TRUE,LEN(AP13)<81,NOT(ISNUMBER(FIND('List of Values'!$C$2:$C$20,AP13)))),"")} -> TRUE | AS13: =D13 -> FIRESAFE SVERIGE AB | AT13: =IF(NOT(ISBLANK($C13)),IF(NOT(ISBLANK(AS13)),TRUE,FALSE),"") -> TRUE | AU13: {=IF(NOT(ISBLANK($C13)),AND(AT13=TRUE,LEN(AS13)<81,NOT(ISNUMBER(FIND('List of Values'!$C$2:$C$20,AS13)))),"")} -> TRUE | AV13: KIDDESWEDEN | AW13: =IF(NOT(ISBLANK($C13)),IF(NOT(ISBLANK(AV13)),TRUE,FALSE),"") -> TRUE | AX13: {=IF(NOT(ISBLANK($C13)),AND(AW13=TRUE,LEN(AV13)<21,NOT(ISNUMBER(FIND('List of Values'!$C$2:$C$20,AV13)))),"")} -> TRUE | AY13: 10001 | AZ13: =IF(NOT(ISBLANK($C13)),TRUE,"") -> TRUE | BA13: =IF(NOT(ISBLANK($C13)),AND(AZ13=TRUE,NOT(COUNTIF('List of Values'!$R$2:$R$400,AY13)=0)),"") -> TRUE | BC13: =IF(NOT(ISBLANK($C13)),TRUE,"") -> TRUE | BD13: {=IF(NOT(ISBLANK($C13)),OR(ISBLANK(BB13),AND(NOT(ISNUMBER(FIND('List of Values'!$C$2:$C$23,BB13))),ISNUMBER(DATEVALUE(BB13)))),"")} -> TRUE | BF13: =IF(NOT(ISBLANK($C13)),TRUE,"") -> TRUE | BG13: {=IF(NOT(ISBLANK($C13)),OR(ISBLANK(BE13),AND(NOT(ISNUMBER(FIND('List of Values'!$C$2:$C$23,BE13))),ISNUMBER(DATEVALUE(BE13)))),"")} -> TRUE | BI13: =IF(NOT(ISBLANK($C13)),TRUE,"") -> TRUE | BJ13: =IF(NOT(ISBLANK($C13)),OR(ISBLANK(BH13),AND(LEN(BH13)<14,ISNUMBER(BH13))),"") -> TRUE | BK13: Invoice | BL13: =IF(NOT(ISBLANK($C13)),IF(NOT(ISBLANK(BK13)),TRUE,FALSE),"") -> TRUE | BM13: =IF(NOT(ISBLANK($C13)),AND(BL13=TRUE,NOT(COUNTIF('List of Values'!$A$2:$A$20,BK13)=0)),"") -> TRUE | BN13: Active | BO13: =IF(NOT(ISBLANK($C13)),IF(NOT(ISBLANK(BN13)),TRUE,FALSE),"") -> TRUE | BP13: =IF(NOT(ISBLANK($C13)),OR(BN13="active",BN13="delisted"),"") -> TRUE | BR13: =IF(NOT(ISBLANK($C13)),OR(AND($E13="intercompany",NOT(ISBLANK(BQ13))),AND(NOT($E13="intercompany"),ISBLANK(BQ13))),"") -> TRUE | BS13: =IF(NOT(ISBLANK($C13)),OR(ISBLANK(BQ13),NOT(COUNTIF('List of Values'!$K$2:$K$30,BQ13)=0)),"") -> TRUE | BU13: =IF(NOT(ISBLANK($C13)),TRUE,"") -> TRUE | BV13: =IF(NOT(ISBLANK($C13)),OR(ISBLANK(BT13),BT13="duty paid",BT13="bond"),"") -> TRUE | BX13: =IF(NOT(ISBLANK($C13)),TRUE,"") -> TRUE | BY13: =IF(NOT(ISBLANK($C13)),OR(ISBLANK(BW13),BW13="duty paid",BW13="bond"),"") -> TRUE | BZ13: =_xlfn.XLOOKUP(C13,[1]Blad1!$A:$A,[1]Blad1!$D:$D,"")
B14: =COUNTIF(C14:XFD14,"FALSE") -> 0 | C14: 217966 | D14: HOKKAI SUISAN SWEDEN AB | E14: Trade | F14: 5567159867 | G14: =IF(NOT(ISBLANK($C14)),IF(NOT(ISBLANK(F14)),TRUE,FALSE),"") -> TRUE | H14: {=IF(NOT(ISBLANK($C14)),AND(G14=TRUE,LEN(F14)<30,NOT(ISNUMBER(FIND('List of Values'!$C$2:$C$20,F14)))),"")} -> TRUE | I14: SE556715986701 | J14: =IF(NOT(ISBLANK($C14)),TRUE,"") -> TRUE | K14: {=IF(NOT(ISBLANK($C14)),AND(J14=TRUE,LEN(I14)<20,NOT(ISNUMBER(FIND('List of Values'!$C$2:$C$20,I14)))),"")} -> TRUE | L14: FISKHALLSVÄGEN 16 | M14: =IF(NOT(ISBLANK($C14)),IF(NOT(ISBLANK(L14)),TRUE,FALSE),"") -> TRUE | N14: {=IF(NOT(ISBLANK($C14)),AND(M14=TRUE,LEN(L14)<81,NOT(ISNUMBER(FIND('List of Values'!$C$2:$C$20,L14)))),"")} -> TRUE | P14: =IF(NOT(ISBLANK($C14)),TRUE,"") -> TRUE | Q14: {=IF(NOT(ISBLANK($C14)),AND(P14=TRUE,LEN(O14)<81,NOT(ISNUMBER(FIND('List of Values'!$C$2:$C$20,O14)))),"")} -> TRUE | R14: ÅRSTA | S14: =IF(NOT(ISBLANK($C14)),IF(NOT(ISBLANK(R14)),TRUE,FALSE),"") -> TRUE | T14: {=IF(NOT(ISBLANK($C14)),AND(S14=TRUE,LEN(R14)<61,NOT(ISNUMBER(FIND('List of Values'!$C$2:$C$23,R14)))),"")} -> TRUE | V14: =IF(NOT(ISBLANK($C14)),TRUE,"") -> TRUE | W14: {=IF(NOT(ISBLANK($C14)),AND(V14=TRUE,LEN(U14)<61,NOT(ISNUMBER(FIND('List of Values'!$C$2:$C$23,U14)))),"")} -> TRUE | X14: 120 44 | Y14: =IF(NOT(ISBLANK($C14)),IF(NOT(ISBLANK(X14)),TRUE,FALSE),"") -> TRUE | Z14: {=IF(NOT(ISBLANK($C14)),AND(Y14=TRUE,LEN(X14)<81,NOT(ISNUMBER(FIND('List of Values'!$C$2:$C$23,X14)))),"")} -> TRUE | AA14: SE | AB14: =IF(NOT(ISBLANK($C14)),IF(NOT(ISBLANK(AA14)),TRUE,FALSE),"") -> TRUE | AC14: =IF(NOT(ISBLANK($C14)),AND(AB14=TRUE,NOT(COUNTIF('List of Values'!$B$2:$B$255,AA14)=0)),"") -> TRUE | AD14: SEK | AE14: =IF(NOT(ISBLANK($C14)),IF(NOT(ISBLANK(AD14)),TRUE,FALSE),"") -> TRUE | AF14: =IF(NOT(ISBLANK($C14)),AND(AE14=TRUE,NOT(COUNTIF('List of Values'!$F$2:$F$255,AD14)=0)),"") -> TRUE | AG14: V_10EOM | AH14: =IF(NOT(ISBLANK($C14)),IF(NOT(ISBLANK(AG14)),TRUE,FALSE),"") -> TRUE | AI14: =IF(NOT(ISBLANK($C14)),AND(AH14=TRUE,NOT(COUNTIF('List of Values'!$N$2:$N$40,AG14)=0)),"") -> TRUE | AJ14: V_BANK | AK14: =IF(NOT(ISBLANK($C14)),IF(NOT(ISBLANK(AJ14)),TRUE,FALSE),"") -> TRUE | AL14: =IF(NOT(ISBLANK($C14)),AND(AK14=TRUE,NOT(COUNTIF('List of Values'!$O$2:$O$30,AJ14)=0)),"") -> TRUE | AM14: S-DOM | AN14: =IF(NOT(ISBLANK($C14)),IF(NOT(ISBLANK(AM14)),TRUE,FALSE),"") -> TRUE | AO14: =IF(NOT(ISBLANK($C14)),AND(AN14=TRUE,NOT(COUNTIF('List of Values'!$AF$2:$AF$20,AM14)=0)),"") -> TRUE | AQ14: =IF(NOT(ISBLANK($C14)),TRUE,"") -> TRUE | AR14: {=IF(NOT(ISBLANK($C14)),AND(AQ14=TRUE,LEN(AP14)<81,NOT(ISNUMBER(FIND('List of Values'!$C$2:$C$20,AP14)))),"")} -> TRUE | AS14: =D14 -> HOKKAI SUISAN SWEDEN AB | AT14: =IF(NOT(ISBLANK($C14)),IF(NOT(ISBLANK(AS14)),TRUE,FALSE),"") -> TRUE | AU14: {=IF(NOT(ISBLANK($C14)),AND(AT14=TRUE,LEN(AS14)<81,NOT(ISNUMBER(FIND('List of Values'!$C$2:$C$20,AS14)))),"")} -> TRUE | AV14: HOKKAISUISANSWEDENAB | AW14: =IF(NOT(ISBLANK($C14)),IF(NOT(ISBLANK(AV14)),TRUE,FALSE),"") -> TRUE | AX14: {=IF(NOT(ISBLANK($C14)),AND(AW14=TRUE,LEN(AV14)<21,NOT(ISNUMBER(FIND('List of Values'!$C$2:$C$20,AV14)))),"")} -> TRUE | AY14: 12492 | AZ14: =IF(NOT(ISBLANK($C14)),TRUE,"") -> TRUE | BA14: =IF(NOT(ISBLANK($C14)),AND(AZ14=TRUE,NOT(COUNTIF('List of Values'!$R$2:$R$400,AY14)=0)),"") -> TRUE | BC14: =IF(NOT(ISBLANK($C14)),TRUE,"") -> TRUE | BD14: {=IF(NOT(ISBLANK($C14)),OR(ISBLANK(BB14),AND(NOT(ISNUMBER(FIND('List of Values'!$C$2:$C$23,BB14))),ISNUMBER(DATEVALUE(BB14)))),"")} -> TRUE | BF14: =IF(NOT(ISBLANK($C14)),TRUE,"") -> TRUE | BG14: {=IF(NOT(ISBLANK($C14)),OR(ISBLANK(BE14),AND(NOT(ISNUMBER(FIND('List of Values'!$C$2:$C$23,BE14))),ISNUMBER(DATEVALUE(BE14)))),"")} -> TRUE | BI14: =IF(NOT(ISBLANK($C14)),TRUE,"") -> TRUE | BJ14: =IF(NOT(ISBLANK($C14)),OR(ISBLANK(BH14),AND(LEN(BH14)<14,ISNUMBER(BH14))),"") -> TRUE | BK14: Invoice | BL14: =IF(NOT(ISBLANK($C14)),IF(NOT(ISBLANK(BK14)),TRUE,FALSE),"") -> TRUE | BM14: =IF(NOT(ISBLANK($C14)),AND(BL14=TRUE,NOT(COUNTIF('List of Values'!$A$2:$A$20,BK14)=0)),"") -> TRUE | BN14: Active | BO14: =IF(NOT(ISBLANK($C14)),IF(NOT(ISBLANK(BN14)),TRUE,FALSE),"") -> TRUE | BP14: =IF(NOT(ISBLANK($C14)),OR(BN14="active",BN14="delisted"),"") -> TRUE | BR14: =IF(NOT(ISBLANK($C14)),OR(AND($E14="intercompany",NOT(ISBLANK(BQ14))),AND(NOT($E14="intercompany"),ISBLANK(BQ14))),"") -> TRUE | BS14: =IF(NOT(ISBLANK($C14)),OR(ISBLANK(BQ14),NOT(COUNTIF('List of Values'!$K$2:$K$30,BQ14)=0)),"") -> TRUE | BU14: =IF(NOT(ISBLANK($C14)),TRUE,"") -> TRUE | BV14: =IF(NOT(ISBLANK($C14)),OR(ISBLANK(BT14),BT14="duty paid",BT14="bond"),"") -> TRUE | BX14: =IF(NOT(ISBLANK($C14)),TRUE,"") -> TRUE | BY14: =IF(NOT(ISBLANK($C14)),OR(ISBLANK(BW14),BW14="duty paid",BW14="bond"),"") -> TRUE | BZ14: =_xlfn.XLOOKUP(C14,[1]Blad1!$A:$A,[1]Blad1!$D:$D,"")
B15: =COUNTIF(C15:XFD15,"FALSE") -> 0 | C15: 217988 | D15: JUST SEAFOOD DK | E15: Trade | F15: DK42785342 | G15: =IF(NOT(ISBLANK($C15)),IF(NOT(ISBLANK(F15)),TRUE,FALSE),"") -> TRUE | H15: {=IF(NOT(ISBLANK($C15)),AND(G15=TRUE,LEN(F15)<30,NOT(ISNUMBER(FIND('List of Values'!$C$2:$C$20,F15)))),"")} -> TRUE | I15: DK42785342 | J15: =IF(NOT(ISBLANK($C15)),TRUE,"") -> TRUE | K15: {=IF(NOT(ISBLANK($C15)),AND(J15=TRUE,LEN(I15)<20,NOT(ISNUMBER(FIND('List of Values'!$C$2:$C$20,I15)))),"")} -> TRUE | L15: KAI LINDBERGS GADE 41 | M15: =IF(NOT(ISBLANK($C15)),IF(NOT(ISBLANK(L15)),TRUE,FALSE),"") -> TRUE | N15: {=IF(NOT(ISBLANK($C15)),AND(M15=TRUE,LEN(L15)<81,NOT(ISNUMBER(FIND('List of Values'!$C$2:$C$20,L15)))),"")} -> TRUE | P15: =IF(NOT(ISBLANK($C15)),TRUE,"") -> TRUE | Q15: {=IF(NOT(ISBLANK($C15)),AND(P15=TRUE,LEN(O15)<81,NOT(ISNUMBER(FIND('List of Values'!$C$2:$C$20,O15)))),"")} -> TRUE | R15: HANSTHOLM | S15: =IF(NOT(ISBLANK($C15)),IF(NOT(ISBLANK(R15)),TRUE,FALSE),"") -> TRUE | T15: {=IF(NOT(ISBLANK($C15)),AND(S15=TRUE,LEN(R15)<61,NOT(ISNUMBER(FIND('List of Values'!$C$2:$C$23,R15)))),"")} -> TRUE | V15: =IF(NOT(ISBLANK($C15)),TRUE,"") -> TRUE | W15: {=IF(NOT(ISBLANK($C15)),AND(V15=TRUE,LEN(U15)<61,NOT(ISNUMBER(FIND('List of Values'!$C$2:$C$23,U15)))),"")} -> TRUE | X15: DK-7730 | Y15: =IF(NOT(ISBLANK($C15)),IF(NOT(ISBLANK(X15)),TRUE,FALSE),"") -> TRUE | Z15: {=IF(NOT(ISBLANK($C15)),AND(Y15=TRUE,LEN(X15)<81,NOT(ISNUMBER(FIND('List of Values'!$C$2:$C$23,X15)))),"")} -> TRUE | AA15: DK | AB15: =IF(NOT(ISBLANK($C15)),IF(NOT(ISBLANK(AA15)),TRUE,FALSE),"") -> TRUE | AC15: =IF(NOT(ISBLANK($C15)),AND(AB15=TRUE,NOT(COUNTIF('List of Values'!$B$2:$B$255,AA15)=0)),"") -> TRUE | AD15: SEK | AE15: =IF(NOT(ISBLANK($C15)),IF(NOT(ISBLANK(AD15)),TRUE,FALSE),"") -> TRUE | AF15: =IF(NOT(ISBLANK($C15)),AND(AE15=TRUE,NOT(COUNTIF('List of Values'!$F$2:$F$255,AD15)=0)),"") -> TRUE | AG15: V_10EOM | AH15: =IF(NOT(ISBLANK($C15)),IF(NOT(ISBLANK(AG15)),TRUE,FALSE),"") -> TRUE | AI15: =IF(NOT(ISBLANK($C15)),AND(AH15=TRUE,NOT(COUNTIF('List of Values'!$N$2:$N$40,AG15)=0)),"") -> TRUE | AJ15: V_BANK | AK15: =IF(NOT(ISBLANK($C15)),IF(NOT(ISBLANK(AJ15)),TRUE,FALSE),"") -> TRUE | AL15: =IF(NOT(ISBLANK($C15)),AND(AK15=TRUE,NOT(COUNTIF('List of Values'!$O$2:$O$30,AJ15)=0)),"") -> TRUE | AM15: S-EU | AN15: =IF(NOT(ISBLANK($C15)),IF(NOT(ISBLANK(AM15)),TRUE,FALSE),"") -> TRUE | AO15: =IF(NOT(ISBLANK($C15)),AND(AN15=TRUE,NOT(COUNTIF('List of Values'!$AF$2:$AF$20,AM15)=0)),"") -> TRUE | AQ15: =IF(NOT(ISBLANK($C15)),TRUE,"") -> TRUE | AR15: {=IF(NOT(ISBLANK($C15)),AND(AQ15=TRUE,LEN(AP15)<81,NOT(ISNUMBER(FIND('List of Values'!$C$2:$C$20,AP15)))),"")} -> TRUE | AS15: =D15 -> JUST SEAFOOD DK | AT15: =IF(NOT(ISBLANK($C15)),IF(NOT(ISBLANK(AS15)),TRUE,FALSE),"") -> TRUE | AU15: {=IF(NOT(ISBLANK($C15)),AND(AT15=TRUE,LEN(AS15)<81,NOT(ISNUMBER(FIND('List of Values'!$C$2:$C$20,AS15)))),"")} -> TRUE | AV15: JUSTSEAFOODDK | AW15: =IF(NOT(ISBLANK($C15)),IF(NOT(ISBLANK(AV15)),TRUE,FALSE),"") -> TRUE | AX15: {=IF(NOT(ISBLANK($C15)),AND(AW15=TRUE,LEN(AV15)<21,NOT(ISNUMBER(FIND('List of Values'!$C$2:$C$20,AV15)))),"")} -> TRUE | AY15: 12783 | AZ15: =IF(NOT(ISBLANK($C15)),TRUE,"") -> TRUE | BA15: =IF(NOT(ISBLANK($C15)),AND(AZ15=TRUE,NOT(COUNTIF('List of Values'!$R$2:$R$400,AY15)=0)),"") -> TRUE | BC15: =IF(NOT(ISBLANK($C15)),TRUE,"") -> TRUE | BD15: {=IF(NOT(ISBLANK($C15)),OR(ISBLANK(BB15),AND(NOT(ISNUMBER(FIND('List of Values'!$C$2:$C$23,BB15))),ISNUMBER(DATEVALUE(BB15)))),"")} -> TRUE | BF15: =IF(NOT(ISBLANK($C15)),TRUE,"") -> TRUE | BG15: {=IF(NOT(ISBLANK($C15)),OR(ISBLANK(BE15),AND(NOT(ISNUMBER(FIND('List of Values'!$C$2:$C$23,BE15))),ISNUMBER(DATEVALUE(BE15)))),"")} -> TRUE | BI15: =IF(NOT(ISBLANK($C15)),TRUE,"") -> TRUE | BJ15: =IF(NOT(ISBLANK($C15)),OR(ISBLANK(BH15),AND(LEN(BH15)<14,ISNUMBER(BH15))),"") -> TRUE | BK15: Invoice | BL15: =IF(NOT(ISBLANK($C15)),IF(NOT(ISBLANK(BK15)),TRUE,FALSE),"") -> TRUE | BM15: =IF(NOT(ISBLANK($C15)),AND(BL15=TRUE,NOT(COUNTIF('List of Values'!$A$2:$A$20,BK15)=0)),"") -> TRUE | BN15: Active | BO15: =IF(NOT(ISBLANK($C15)),IF(NOT(ISBLANK(BN15)),TRUE,FALSE),"") -> TRUE | BP15: =IF(NOT(ISBLANK($C15)),OR(BN15="active",BN15="delisted"),"") -> TRUE | BR15: =IF(NOT(ISBLANK($C15)),OR(AND($E15="intercompany",NOT(ISBLANK(BQ15))),AND(NOT($E15="intercompany"),ISBLANK(BQ15))),"") -> TRUE | BS15: =IF(NOT(ISBLANK($C15)),OR(ISBLANK(BQ15),NOT(COUNTIF('List of Values'!$K$2:$K$30,BQ15)=0)),"") -> TRUE | BU15: =IF(NOT(ISBLANK($C15)),TRUE,"") -> TRUE | BV15: =IF(NOT(ISBLANK($C15)),OR(ISBLANK(BT15),BT15="duty paid",BT15="bond"),"") -> TRUE | BX15: =IF(NOT(ISBLANK($C15)),TRUE,"") -> TRUE | BY15: =IF(NOT(ISBLANK($C15)),OR(ISBLANK(BW15),BW15="duty paid",BW15="bond"),"") -> TRUE | BZ15: =_xlfn.XLOOKUP(C15,[1]Blad1!$A:$A,[1]Blad1!$D:$D,"")
B16: =COUNTIF(C16:XFD16,"FALSE") -> 0 | C16: 218002 | D16: MAREA ALTRA BV | E16: Trade | F16: NL805410491B01 | G16: =IF(NOT(ISBLANK($C16)),IF(NOT(ISBLANK(F16)),TRUE,FALSE),"") -> TRUE | H16: {=IF(NOT(ISBLANK($C16)),AND(G16=TRUE,LEN(F16)<30,NOT(ISNUMBER(FIND('List of Values'!$C$2:$C$20,F16)))),"")} -> TRUE | I16: NL805410491B01 | J16: =IF(NOT(ISBLANK($C16)),TRUE,"") -> TRUE | K16: {=IF(NOT(ISBLANK($C16)),AND(J16=TRUE,LEN(I16)<20,NOT(ISNUMBER(FIND('List of Values'!$C$2:$C$20,I16)))),"")} -> TRUE | L16: BOX 12 | M16: =IF(NOT(ISBLANK($C16)),IF(NOT(ISBLANK(L16)),TRUE,FALSE),"") -> TRUE | N16: {=IF(NOT(ISBLANK($C16)),AND(M16=TRUE,LEN(L16)<81,NOT(ISNUMBER(FIND('List of Values'!$C$2:$C$20,L16)))),"")} -> TRUE | P16: =IF(NOT(ISBLANK($C16)),TRUE,"") -> TRUE | Q16: {=IF(NOT(ISBLANK($C16)),AND(P16=TRUE,LEN(O16)<81,NOT(ISNUMBER(FIND('List of Values'!$C$2:$C$20,O16)))),"")} -> TRUE | R16: URK | S16: =IF(NOT(ISBLANK($C16)),IF(NOT(ISBLANK(R16)),TRUE,FALSE),"") -> TRUE | T16: {=IF(NOT(ISBLANK($C16)),AND(S16=TRUE,LEN(R16)<61,NOT(ISNUMBER(FIND('List of Values'!$C$2:$C$23,R16)))),"")} -> TRUE | V16: =IF(NOT(ISBLANK($C16)),TRUE,"") -> TRUE | W16: {=IF(NOT(ISBLANK($C16)),AND(V16=TRUE,LEN(U16)<61,NOT(ISNUMBER(FIND('List of Values'!$C$2:$C$23,U16)))),"")} -> TRUE | X16: NL-8320 AA | Y16: =IF(NOT(ISBLANK($C16)),IF(NOT(ISBLANK(X16)),TRUE,FALSE),"") -> TRUE | Z16: {=IF(NOT(ISBLANK($C16)),AND(Y16=TRUE,LEN(X16)<81,NOT(ISNUMBER(FIND('List of Values'!$C$2:$C$23,X16)))),"")} -> TRUE | AA16: NL | AB16: =IF(NOT(ISBLANK($C16)),IF(NOT(ISBLANK(AA16)),TRUE,FALSE),"") -> TRUE | AC16: =IF(NOT(ISBLANK($C16)),AND(AB16=TRUE,NOT(COUNTIF('List of Values'!$B$2:$B$255,AA16)=0)),"") -> TRUE | AD16: EUR | AE16: =IF(NOT(ISBLANK($C16)),IF(NOT(ISBLANK(AD16)),TRUE,FALSE),"") -> TRUE | AF16: =IF(NOT(ISBLANK($C16)),AND(AE16=TRUE,NOT(COUNTIF('List of Values'!$F$2:$F$255,AD16)=0)),"") -> TRUE | AG16: V_30NET | AH16: =IF(NOT(ISBLANK($C16)),IF(NOT(ISBLANK(AG16)),TRUE,FALSE),"") -> TRUE | AI16: =IF(NOT(ISBLANK($C16)),AND(AH16=TRUE,NOT(COUNTIF('List of Values'!$N$2:$N$40,AG16)=0)),"") -> TRUE | AJ16: V_BANK | AK16: =IF(NOT(ISBLANK($C16)),IF(NOT(ISBLANK(AJ16)),TRUE,FALSE),"") -> TRUE | AL16: =IF(NOT(ISBLANK($C16)),AND(AK16=TRUE,NOT(COUNTIF('List of Values'!$O$2:$O$30,AJ16)=0)),"") -> TRUE | AM16: S-EU | AN16: =IF(NOT(ISBLANK($C16)),IF(NOT(ISBLANK(AM16)),TRUE,FALSE),"") -> TRUE | AO16: =IF(NOT(ISBLANK($C16)),AND(AN16=TRUE,NOT(COUNTIF('List of Values'!$AF$2:$AF$20,AM16)=0)),"") -> TRUE | AQ16: =IF(NOT(ISBLANK($C16)),TRUE,"") -> TRUE | AR16: {=IF(NOT(ISBLANK($C16)),AND(AQ16=TRUE,LEN(AP16)<81,NOT(ISNUMBER(FIND('List of Values'!$C$2:$C$20,AP16)))),"")} -> TRUE | AS16: =D16 -> MAREA ALTRA BV | AT16: =IF(NOT(ISBLANK($C16)),IF(NOT(ISBLANK(AS16)),TRUE,FALSE),"") -> TRUE | AU16: {=IF(NOT(ISBLANK($C16)),AND(AT16=TRUE,LEN(AS16)<81,NOT(ISNUMBER(FIND('List of Values'!$C$2:$C$20,AS16)))),"")} -> TRUE | AV16: MAREAALTRA | AW16: =IF(NOT(ISBLANK($C16)),IF(NOT(ISBLANK(AV16)),TRUE,FALSE),"") -> TRUE | AX16: {=IF(NOT(ISBLANK($C16)),AND(AW16=TRUE,LEN(AV16)<21,NOT(ISNUMBER(FIND('List of Values'!$C$2:$C$20,AV16)))),"")} -> TRUE | AY16: 13292 | AZ16: =IF(NOT(ISBLANK($C16)),TRUE,"") -> TRUE | BA16: =IF(NOT(ISBLANK($C16)),AND(AZ16=TRUE,NOT(COUNTIF('List of Values'!$R$2:$R$400,AY16)=0)),"") -> TRUE | BC16: =IF(NOT(ISBLANK($C16)),TRUE,"") -> TRUE | BD16: {=IF(NOT(ISBLANK($C16)),OR(ISBLANK(BB16),AND(NOT(ISNUMBER(FIND('List of Values'!$C$2:$C$23,BB16))),ISNUMBER(DATEVALUE(BB16)))),"")} -> TRUE | BF16: =IF(NOT(ISBLANK($C16)),TRUE,"") -> TRUE | BG16: {=IF(NOT(ISBLANK($C16)),OR(ISBLANK(BE16),AND(NOT(ISNUMBER(FIND('List of Values'!$C$2:$C$23,BE16))),ISNUMBER(DATEVALUE(BE16)))),"")} -> TRUE | BI16: =IF(NOT(ISBLANK($C16)),TRUE,"") -> TRUE | BJ16: =IF(NOT(ISBLANK($C16)),OR(ISBLANK(BH16),AND(LEN(BH16)<14,ISNUMBER(BH16))),"") -> TRUE | BK16: Invoice | BL16: =IF(NOT(ISBLANK($C16)),IF(NOT(ISBLANK(BK16)),TRUE,FALSE),"") -> TRUE | BM16: =IF(NOT(ISBLANK($C16)),AND(BL16=TRUE,NOT(COUNTIF('List of Values'!$A$2:$A$20,BK16)=0)),"") -> TRUE | BN16: Active | BO16: =IF(NOT(ISBLANK($C16)),IF(NOT(ISBLANK(BN16)),TRUE,FALSE),"") -> TRUE | BP16: =IF(NOT(ISBLANK($C16)),OR(BN16="active",BN16="delisted"),"") -> TRUE | BR16: =IF(NOT(ISBLANK($C16)),OR(AND($E16="intercompany",NOT(ISBLANK(BQ16))),AND(NOT($E16="intercompany"),ISBLANK(BQ16))),"") -> TRUE | BS16: =IF(NOT(ISBLANK($C16)),OR(ISBLANK(BQ16),NOT(COUNTIF('List of Values'!$K$2:$K$30,BQ16)=0)),"") -> TRUE | BU16: =IF(NOT(ISBLANK($C16)),TRUE,"") -> TRUE | BV16: =IF(NOT(ISBLANK($C16)),OR(ISBLANK(BT16),BT16="duty paid",BT16="bond"),"") -> TRUE | BX16: =IF(NOT(ISBLANK($C16)),TRUE,"") -> TRUE | BY16: =IF(NOT(ISBLANK($C16)),OR(ISBLANK(BW16),BW16="duty paid",BW16="bond"),"") -> TRUE | BZ16: =_xlfn.XLOOKUP(C16,[1]Blad1!$A:$A,[1]Blad1!$D:$D,"") -> x
